Workbook

Sheet RIEPILOGO_RIMBORSO_SPESE
K1: Doc Nota Spese rev.06
K2: Riassunto spese trasferta - modulo
A4: RIASSUNTO SPESE TRASFERTA
F6: Rif EBS:
F7: Autore:
F8: ATTENZIONE!!! ERRORE COMPILAZIONE ELENCO_SPESE
A9: DATI TRASFERTA | D9: GESTIONE CONTANTI | G9: SPESE FATTURATE PAGATE DA CONTO BS | AC9: Traf. Commerciale IT | AD9: =RIMBORSO_SPESE!BL9+RIMBORSO_SPESE!BM9+RIMBORSO_SPESE!BN9 -> 0
A10: Data Inizio : | D10: Euro anticipati | E10: 0 | G10: Causale | J10: Importo | AC10: Traf. Commerciale EXT
A11: Data Fine : | D11: Euro prelevati CC | E11: =RIMBORSO_SPESE!AQ9 -> 0 | G11: Confort Viaggi rif: | J11: 0 | AC11: Fiera
A12: Cliente : | D12: Euro contanti spesi | E12: =RIMBORSO_SPESE!AV9+E18 -> 0 | G12: TAXI EMMEPI, | J12: 0 | L12: NB: In mancanza del dettaglio costi utilizzare costi indicativi in nota | AC12: Visita Fornitori
A13: Luogo : | D13: Euro resi | E13: 0 | G13: AVIS | J13: 0 | AC13: Altro (vedi causale)
A14: Tipo : | D14: Rimanenza Euro | E14: =E10+E11-E12-E13 -> 0 | AC14: AST-Installazione
A15: Causale: | D15: VALUTA ESTERA | AC15: AST-In Garanzia
D16: Tipo Valuta | E16: --- | AC16: AST-Fuori Garanzia
A17: Centro Costo/PRG : | D17: Valuta anticipata | E17: 0 | G17: RIMBORSO CHILOMETRICO PER USO AUTO PRORPIA | AC17: AST-A Contratto
A18: Dip. Esecutore : | D18: Tot € Cambiati | E18: =RIMBORSO_SPESE!AM9-RIMBORSO_SPESE!AO9 -> 0 | G18: Tot km da Rimborsare: | I18: ='RIMBORSO KM'!G57 -> 0 | J18: Importo | K18: =I18*0.3 -> 0 | AC18: AST-Promozionale
A19: Altro Personale BS 1 : | D19: Tot Valuta da Cambi | E19: =RIMBORSO_SPESE!AN9-RIMBORSO_SPESE!AP9 -> 0 | G19: RIASSUNTO DATI CONTABILI
A20: Altro Personale BS 2 : | D20: Valuta Prelevata CC | E20: =RIMBORSO_SPESE!AR9 -> 0 | G20: Causale | I20: Tot (in Euro) | J20: Tot (in Valuta)
A21: Altro Personale BS 3 : | D21: Tot Valuta Spesa (contanti) | E21: =RIMBORSO_SPESE!AW9 -> 0 | G21: Tot Pagamenti CC | I21: =RIMBORSO_SPESE!AT9 -> 0 | J21: =IF($E$25<>0,((RIMBORSO_SPESE!AU9)/$E$25),0) -> 0
A22: Targa Auto EBS : | D22: Valuta da rendere | E22: =E17+E19+E20-E21 -> 0 | G22: Pagamenti in Contanti | I22: =RIMBORSO_SPESE!AV9 -> 0 | J22: =IF($E$25<>0,((RIMBORSO_SPESE!AW9)/$E$25),0) -> 0
D23: Valuta Resa | E23: 0 | G23: Non Giustificate | I23: =RIMBORSO_SPESE!AY9+RIMBORSO_SPESE!AZ9 -> 0 | J23: =IF($E$25<>0,((RIMBORSO_SPESE!BA9+RIMBORSO_SPESE!BB9)/$E$25),0) -> 0
A24: N° Notti Italia : | D24: Differenza ricevuta-resa | E24: =(E22-E23) -> 0 | G24: Rifornimenti IT | I24: =RIMBORSO_SPESE!AK9 -> 0
A25: N° Notti Estero : | D25: Tasso di cambio di rif. | E25: 1 | G25: Fiera | I25: =RIMBORSO_SPESE!BG9+RIMBORSO_SPESE!BH9 -> 0 | J25: =IF($E$25<>0,((RIMBORSO_SPESE!BI9+RIMBORSO_SPESE!BJ9)/$E$25),0) -> 0
A27: TOTALI PER SINGOLE CAUSALI | H27: TOTALI CONTABILI
A28: Causale | C28: Euro | D28: Valuta | E28: Tot € | H28: € Tot Contabile (Cont. + CC) | J28: =SUM(I21:J22) -> 0
A29: Vitto/Alloggio | C29: =RIMBORSO_SPESE!AE9 -> 0 | D29: =RIMBORSO_SPESE!AF9 -> 0 | E29: =C29+IF($E$25<>0,(D29/$E$25),0) -> 0 | H29: € Tot Trasferta | J29: =J28+SUM(J11:K16)+K18 -> 0
A30: Varie | C30: =RIMBORSO_SPESE!AG9 -> 0 | D30: =RIMBORSO_SPESE!AH9 -> 0 | E30: =C30+IF($E$25<>0,(D30/$E$25),0) -> 0 | H30: Costo medio giornaliero | J30: =IF(C24+C25>0,J29/(C24+C25+1),"")
A31: Spostamenti | C31: =RIMBORSO_SPESE!AI9+RIMBORSO_SPESE!AK9 -> 0 | D31: =RIMBORSO_SPESE!AJ9+RIMBORSO_SPESE!AL9 -> 0 | E31: =C31+IF($E$25<>0,(D31/$E$25),0) -> 0 | H31: € Tot da Restituire | J31: =(E14* -1) +K18 -> 0
A33: FIRMA DIPENDENTE | G33: APPROVAZIONE

Sheet RIMBORSO_SPESE
K1: Doc. Rimborso spese rev.06
K2: Elenco spese uscita/trasferta - modulo
A4: ELENCO SPESE USCITA/TRASFERTA
E5: Causale:
E6: Autore:
E7: Firma:
A8: N° Ric. | B8: Data | C8: Tipo | D8: Causale | E8: Importo | G8: Mod. Pagamento | H8: Con Fattura | I8: NON Giustific. | J8: Rappresentanza | K8: Fiera | AE8: Euro | AF8: Valuta | AG8: Euro | AH8: Valuta | AI8: Euro | AJ8: Valuta | AK8: Euro | AL8: Valuta | AM8: Euro | AN8: Valuta | AO8: Euro | AP8: Valuta | AQ8: Euro | AR8: Valuta | AT8: Euro | AU8: Valuta | AV8: Euro | AW8: Valuta | AY8: Contanti | AZ8: CC | BA8: Contanti | BB8: CC | BC8: Contanti | BD8: CC | BE8: Contanti | BF8: CC | BG8: Contanti | BH8: CC | BI8: Contanti | BJ8: CC
E9: € | F9: Valuta Estera | Z9: CAUSALI SPESE | AA9: CAUSALI PAGAMENTI | AB9: ON/OFF | AD9: TOT | AE9: =SUM(AE11:AE140) -> 0 | AF9: =SUM(AF11:AF140) -> 0 | AG9: =SUM(AG11:AG140) -> 0 | AH9: =SUM(AH11:AH140) -> 0 | AI9: =SUM(AI11:AI140) -> 0 | AJ9: =SUM(AJ11:AJ140) -> 0 | AK9: =SUM(AK11:AK140) -> 0 | AL9: =SUM(AL11:AL140) -> 0 | ... AR9: =SUM(AR11:AR140) -> 0 | AT9: =SUM(AT11:AT140) -> 0 | AU9: =SUM(AU11:AU140) -> 0 | AV9: =SUM(AV11:AV140) -> 0 | AW9: =SUM(AW11:AW140) -> 0 | AY9: =SUM(AY11:AY140) -> 0 | AZ9: =SUM(AZ11:AZ140) -> 0 | BA9: =SUM(BA11:BA140) -> 0 | BB9: =SUM(BB11:BB140) -> 0 | BC9: =SUM(BC11:BC140) -> 0 | BD9: =SUM(BD11:BD140) -> 0 | BE9: =SUM(BE11:BE140) -> 0 | BF9: =SUM(BF11:BF140) -> 0 | ... BJ9: =SUM(BJ11:BJ140) -> 0 | BL9: =SUM(BL10:BL139) -> 0 | BM9: =SUM(BM10:BM139) -> 0 | BN9: =SUM(BN10:BN139) -> 0
D10: TOTALE | E10: =SUM(E11:E140) -> 0 | F10: =SUM(F11:F140) -> 0 | G10: ATTENZIONE!!! ERRORE DI COMPILAZIONE
A11: 1 | Z11: Vitto/Alloggio | AA11: CC-Personale | AE11: =IF($C11=$Z$11,$E11,0) -> 0 | AF11: =IF($C11=$Z$11,$F11,0) -> 0 | AG11: =IF($C11=$Z$12,$E11,0) -> 0 | AH11: =IF($C11=$Z$12,$F11,0) -> 0 | AI11: =IF($C11=$Z$13,$E11,0) -> 0 | AJ11: =IF($C11=$Z$13,$F11,0) -> 0 | AK11: =IF($C11=$Z$14,$E11,0) -> 0 | AL11: =IF($C11=$Z$14,$F11,0) -> 0 | AM11: =IF($C11=$Z$15,$E11,0) -> 0 | AN11: =IF($C11=$Z$15,$F11,0) -> 0 | AO11: =IF($C11=$Z$16,$E11,0) -> 0 | AP11: =IF($C11=$Z$16,$F11,0) -> 0 | AQ11: =IF($C11=$Z$17,$E11,0) -> 0 | AR11: =IF($C11=$Z$17,$F11,0) -> 0 | AT11: =IF(OR($G11=$AA$11,$G11=$AA$13,($G11=$AA$14),$G11=$AA$15),$AE11+$AG11+$AI11+$AK11+$AQ11,0) -> 0 | AU11: =IF(OR($G11=$AA$11,$G11=$AA$13,($G11=$AA$14),$G11=$AA$15),$AF11+$AH11+$AJ11+AL11+AR11,0) -> 0 | AV11: =IF($G11=$AA$12,$AE11+$AG11+$AI11+$AK11+$AQ11,0) -> 0 | AW11: =IF($G11=$AA$12,$AF11+$AH11+$AJ11+$AL11+$AR11,0) -> 0 | AY11: =IF(UPPER($I11) =$AB$12,IF($G11=$AA$12,$AV11,0),0) -> 0 | AZ11: =IF(UPPER($I11) =$AB$12,IF($G11<>$AA$12,$AT11,0),0) -> 0 | BA11: =IF(UPPER($I11) =$AB$12,IF($G11=$AA$12,$AW11,0),0) -> 0 | BB11: =IF(UPPER($I11) =$AB$12,IF($G11<>$AA$12,$AU11,0),0) -> 0 | BC11: =IF(UPPER($J11) =$AB$12,IF($G11=$AA$12,$AV11,0),0) -> 0 | BD11: =IF(UPPER($J11) =$AB$12,IF($G11<>$AA$12,$AT11,0),0) -> 0 | BE11: =IF(UPPER($J11) =$AB$12,IF($G11=$AA$12,$AW11,0),0) -> 0 | BF11: =IF(UPPER($J11) =$AB$12,IF($G11<>$AA$12,$AU11,0),0) -> 0 | BG11: =IF(UPPER($K11) =$AB$12,IF($G11=$AA$12,$AV11,0),0) -> 0 | BH11: =IF(UPPER($K11) =$AB$12,IF($G11<>$AA$12,$AT11,0),0) -> 0 | BI11: =IF(UPPER($K11) =$AB$12,IF($G11=$AA$12,$AW11,0),0) -> 0 | BJ11: =IF(UPPER($K11) =$AB$12,IF($G11<>$AA$12,$AU11,0),0) -> 0 | BL11: =IF(($E11+$F11>0), IF($G11=$AA$10,1,0),0) -> 0 | BM11: =IF(($E11+$F11<=0), IF($G11<>$AA$10,1,0),0) -> 0 | BN11: =IF(($E11+$F11>0), IF($C11=$AA$10,1,0),0) -> 0
A12: 2 | Z12: Varie | AA12: Contante | AB12: X | AE12: =IF($C12=$Z$11,$E12,0) -> 0 | AF12: =IF($C12=$Z$11,$F12,0) -> 0 | AG12: =IF($C12=$Z$12,$E12,0) -> 0 | AH12: =IF($C12=$Z$12,$F12,0) -> 0 | AI12: =IF($C12=$Z$13,$E12,0) -> 0 | AJ12: =IF($C12=$Z$13,$F12,0) -> 0 | AK12: =IF($C12=$Z$14,$E12,0) -> 0 | AL12: =IF($C12=$Z$14,$F12,0) -> 0 | AM12: =IF($C12=$Z$15,$E12,0) -> 0 | AN12: =IF($C12=$Z$15,$F12,0) -> 0 | AO12: =IF($C12=$Z$16,$E12,0) -> 0 | AP12: =IF($C12=$Z$16,$F12,0) -> 0 | AQ12: =IF($C12=$Z$17,$E12,0) -> 0 | AR12: =IF($C12=$Z$17,$F12,0) -> 0 | AT12: =IF(OR($G12=$AA$11,$G12=$AA$13,($G12=$AA$14),$G12=$AA$15),$AE12+$AG12+$AI12+$AK12+$AQ12,0) -> 0 | AU12: =IF(OR($G12=$AA$11,$G12=$AA$13,($G12=$AA$14),$G12=$AA$15),$AF12+$AH12+$AJ12+AL12+AR12,0) -> 0 | AV12: =IF($G12=$AA$12,$AE12+$AG12+$AI12+AK12+AQ12,0) -> 0 | AW12: =IF($G12=$AA$12,$AF12+$AH12+$AJ12+AL12+AR12,0) -> 0 | AY12: =IF(UPPER($I12) =$AB$12,IF($G12=$AA$12,$AV12,0),0) -> 0 | AZ12: =IF(UPPER($I12) =$AB$12,IF($G12<>$AA$12,$AT12,0),0) -> 0 | BA12: =IF(UPPER($I12) =$AB$12,IF($G12=$AA$12,$AW12,0),0) -> 0 | BB12: =IF(UPPER($I12) =$AB$12,IF($G12<>$AA$12,$AU12,0),0) -> 0 | BC12: =IF(UPPER($J12) =$AB$12,IF($G12=$AA$12,$AV12,0),0) -> 0 | BD12: =IF(UPPER($J12) =$AB$12,IF($G12<>$AA$12,$AT12,0),0) -> 0 | BE12: =IF(UPPER($J12) =$AB$12,IF($G12=$AA$12,$AW12,0),0) -> 0 | BF12: =IF(UPPER($J12) =$AB$12,IF($G12<>$AA$12,$AU12,0),0) -> 0 | BG12: =IF(UPPER($K12) =$AB$12,IF($G12=$AA$12,$AV12,0),0) -> 0 | BH12: =IF(UPPER($K12) =$AB$12,IF($G12<>$AA$12,$AT12,0),0) -> 0 | BI12: =IF(UPPER($K12) =$AB$12,IF($G12=$AA$12,$AW12,0),0) -> 0 | BJ12: =IF(UPPER($K12) =$AB$12,IF($G12<>$AA$12,$AU12,0),0) -> 0 | BL12: =IF(($E12+$F12>0), IF($G12=$AA$10,1,0),0) -> 0 | BM12: =IF(($E12+$F12<=0), IF($G12<>$AA$10,1,0),0) -> 0 | BN12: =IF(($E12+$F12>0), IF($C12=$AA$10,1,0),0) -> 0
A13: 3 | Z13: Spostamenti | AA13: CC-Visa | AE13: =IF($C13=$Z$11,$E13,0) -> 0 | AF13: =IF($C13=$Z$11,$F13,0) -> 0 | AG13: =IF($C13=$Z$12,$E13,0) -> 0 | AH13: =IF($C13=$Z$12,$F13,0) -> 0 | AI13: =IF($C13=$Z$13,$E13,0) -> 0 | AJ13: =IF($C13=$Z$13,$F13,0) -> 0 | AK13: =IF($C13=$Z$14,$E13,0) -> 0 | AL13: =IF($C13=$Z$14,$F13,0) -> 0 | AM13: =IF($C13=$Z$15,$E13,0) -> 0 | AN13: =IF($C13=$Z$15,$F13,0) -> 0 | AO13: =IF($C13=$Z$16,$E13,0) -> 0 | AP13: =IF($C13=$Z$16,$F13,0) -> 0 | AQ13: =IF($C13=$Z$17,$E13,0) -> 0 | AR13: =IF($C13=$Z$17,$F13,0) -> 0 | AT13: =IF(OR($G13=$AA$11,$G13=$AA$13,($G13=$AA$14),$G13=$AA$15),$AE13+$AG13+$AI13+$AK13+$AQ13,0) -> 0 | AU13: =IF(OR($G13=$AA$11,$G13=$AA$13,($G13=$AA$14),$G13=$AA$15),$AF13+$AH13+$AJ13+AL13+AR13,0) -> 0 | AV13: =IF($G13=$AA$12,$AE13+$AG13+$AI13+AK13+AQ13,0) -> 0 | AW13: =IF($G13=$AA$12,$AF13+$AH13+$AJ13+AL13+AR13,0) -> 0 | AY13: =IF(UPPER($I13) =$AB$12,IF($G13=$AA$12,$AV13,0),0) -> 0 | AZ13: =IF(UPPER($I13) =$AB$12,IF($G13<>$AA$12,$AT13,0),0) -> 0 | BA13: =IF(UPPER($I13) =$AB$12,IF($G13=$AA$12,$AW13,0),0) -> 0 | BB13: =IF(UPPER($I13) =$AB$12,IF($G13<>$AA$12,$AU13,0),0) -> 0 | BC13: =IF(UPPER($J13) =$AB$12,IF($G13=$AA$12,$AV13,0),0) -> 0 | BD13: =IF(UPPER($J13) =$AB$12,IF($G13<>$AA$12,$AT13,0),0) -> 0 | BE13: =IF(UPPER($J13) =$AB$12,IF($G13=$AA$12,$AW13,0),0) -> 0 | BF13: =IF(UPPER($J13) =$AB$12,IF($G13<>$AA$12,$AU13,0),0) -> 0 | BG13: =IF(UPPER($K13) =$AB$12,IF($G13=$AA$12,$AV13,0),0) -> 0 | BH13: =IF(UPPER($K13) =$AB$12,IF($G13<>$AA$12,$AT13,0),0) -> 0 | BI13: =IF(UPPER($K13) =$AB$12,IF($G13=$AA$12,$AW13,0),0) -> 0 | BJ13: =IF(UPPER($K13) =$AB$12,IF($G13<>$AA$12,$AU13,0),0) -> 0 | BL13: =IF(($E13+$F13>0), IF($G13=$AA$10,1,0),0) -> 0 | BM13: =IF(($E13+$F13<=0), IF($G13<>$AA$10,1,0),0) -> 0 | BN13: =IF(($E13+$F13>0), IF($C13=$AA$10,1,0),0) -> 0
A14: 4 | Z14: Carburante IT | AA14: CC-Master | AE14: =IF($C14=$Z$11,$E14,0) -> 0 | AF14: =IF($C14=$Z$11,$F14,0) -> 0 | AG14: =IF($C14=$Z$12,$E14,0) -> 0 | AH14: =IF($C14=$Z$12,$F14,0) -> 0 | AI14: =IF($C14=$Z$13,$E14,0) -> 0 | AJ14: =IF($C14=$Z$13,$F14,0) -> 0 | AK14: =IF($C14=$Z$14,$E14,0) -> 0 | AL14: =IF($C14=$Z$14,$F14,0) -> 0 | AM14: =IF($C14=$Z$15,$E14,0) -> 0 | AN14: =IF($C14=$Z$15,$F14,0) -> 0 | AO14: =IF($C14=$Z$16,$E14,0) -> 0 | AP14: =IF($C14=$Z$16,$F14,0) -> 0 | AQ14: =IF($C14=$Z$17,$E14,0) -> 0 | AR14: =IF($C14=$Z$17,$F14,0) -> 0 | AT14: =IF(OR($G14=$AA$11,$G14=$AA$13,($G14=$AA$14),$G14=$AA$15),$AE14+$AG14+$AI14+$AK14+$AQ14,0) -> 0 | AU14: =IF(OR($G14=$AA$11,$G14=$AA$13,($G14=$AA$14),$G14=$AA$15),$AF14+$AH14+$AJ14+AL14+AR14,0) -> 0 | AV14: =IF($G14=$AA$12,$AE14+$AG14+$AI14+AK14+AQ14,0) -> 0 | AW14: =IF($G14=$AA$12,$AF14+$AH14+$AJ14+AL14+AR14,0) -> 0 | AY14: =IF(UPPER($I14) =$AB$12,IF($G14=$AA$12,$AV14,0),0) -> 0 | AZ14: =IF(UPPER($I14) =$AB$12,IF($G14<>$AA$12,$AT14,0),0) -> 0 | BA14: =IF(UPPER($I14) =$AB$12,IF($G14=$AA$12,$AW14,0),0) -> 0 | BB14: =IF(UPPER($I14) =$AB$12,IF($G14<>$AA$12,$AU14,0),0) -> 0 | BC14: =IF(UPPER($J14) =$AB$12,IF($G14=$AA$12,$AV14,0),0) -> 0 | BD14: =IF(UPPER($J14) =$AB$12,IF($G14<>$AA$12,$AT14,0),0) -> 0 | BE14: =IF(UPPER($J14) =$AB$12,IF($G14=$AA$12,$AW14,0),0) -> 0 | BF14: =IF(UPPER($J14) =$AB$12,IF($G14<>$AA$12,$AU14,0),0) -> 0 | BG14: =IF(UPPER($K14) =$AB$12,IF($G14=$AA$12,$AV14,0),0) -> 0 | BH14: =IF(UPPER($K14) =$AB$12,IF($G14<>$AA$12,$AT14,0),0) -> 0 | BI14: =IF(UPPER($K14) =$AB$12,IF($G14=$AA$12,$AW14,0),0) -> 0 | BJ14: =IF(UPPER($K14) =$AB$12,IF($G14<>$AA$12,$AU14,0),0) -> 0 | BL14: =IF(($E14+$F14>0), IF($G14=$AA$10,1,0),0) -> 0 | BM14: =IF(($E14+$F14<=0), IF($G14<>$AA$10,1,0),0) -> 0 | BN14: =IF(($E14+$F14>0), IF($C14=$AA$10,1,0),0) -> 0
A15: 5 | Z15: Cambio € -> Valuta | AA15: DKV | AE15: =IF($C15=$Z$11,$E15,0) -> 0 | AF15: =IF($C15=$Z$11,$F15,0) -> 0 | AG15: =IF($C15=$Z$12,$E15,0) -> 0 | AH15: =IF($C15=$Z$12,$F15,0) -> 0 | AI15: =IF($C15=$Z$13,$E15,0) -> 0 | AJ15: =IF($C15=$Z$13,$F15,0) -> 0 | AK15: =IF($C15=$Z$14,$E15,0) -> 0 | AL15: =IF($C15=$Z$14,$F15,0) -> 0 | AM15: =IF($C15=$Z$15,$E15,0) -> 0 | AN15: =IF($C15=$Z$15,$F15,0) -> 0 | AO15: =IF($C15=$Z$16,$E15,0) -> 0 | AP15: =IF($C15=$Z$16,$F15,0) -> 0 | AQ15: =IF($C15=$Z$17,$E15,0) -> 0 | AR15: =IF($C15=$Z$17,$F15,0) -> 0 | AT15: =IF(OR($G15=$AA$11,$G15=$AA$13,($G15=$AA$14),$G15=$AA$15),$AE15+$AG15+$AI15+$AK15+$AQ15,0) -> 0 | AU15: =IF(OR($G15=$AA$11,$G15=$AA$13,($G15=$AA$14),$G15=$AA$15),$AF15+$AH15+$AJ15+AL15+AR15,0) -> 0 | AV15: =IF($G15=$AA$12,$AE15+$AG15+$AI15+AK15+AQ15,0) -> 0 | AW15: =IF($G15=$AA$12,$AF15+$AH15+$AJ15+AL15+AR15,0) -> 0 | AY15: =IF(UPPER($I15) =$AB$12,IF($G15=$AA$12,$AV15,0),0) -> 0 | AZ15: =IF(UPPER($I15) =$AB$12,IF($G15<>$AA$12,$AT15,0),0) -> 0 | BA15: =IF(UPPER($I15) =$AB$12,IF($G15=$AA$12,$AW15,0),0) -> 0 | BB15: =IF(UPPER($I15) =$AB$12,IF($G15<>$AA$12,$AU15,0),0) -> 0 | BC15: =IF(UPPER($J15) =$AB$12,IF($G15=$AA$12,$AV15,0),0) -> 0 | BD15: =IF(UPPER($J15) =$AB$12,IF($G15<>$AA$12,$AT15,0),0) -> 0 | BE15: =IF(UPPER($J15) =$AB$12,IF($G15=$AA$12,$AW15,0),0) -> 0 | BF15: =IF(UPPER($J15) =$AB$12,IF($G15<>$AA$12,$AU15,0),0) -> 0 | BG15: =IF(UPPER($K15) =$AB$12,IF($G15=$AA$12,$AV15,0),0) -> 0 | BH15: =IF(UPPER($K15) =$AB$12,IF($G15<>$AA$12,$AT15,0),0) -> 0 | BI15: =IF(UPPER($K15) =$AB$12,IF($G15=$AA$12,$AW15,0),0) -> 0 | BJ15: =IF(UPPER($K15) =$AB$12,IF($G15<>$AA$12,$AU15,0),0) -> 0 | BL15: =IF(($E15+$F15>0), IF($G15=$AA$10,1,0),0) -> 0 | BM15: =IF(($E15+$F15<=0), IF($G15<>$AA$10,1,0),0) -> 0 | BN15: =IF(($E15+$F15>0), IF($C15=$AA$10,1,0),0) -> 0
A16: 6 | Z16: Cambio Valuta -> € | AE16: =IF($C16=$Z$11,$E16,0) -> 0 | AF16: =IF($C16=$Z$11,$F16,0) -> 0 | AG16: =IF($C16=$Z$12,$E16,0) -> 0 | AH16: =IF($C16=$Z$12,$F16,0) -> 0 | AI16: =IF($C16=$Z$13,$E16,0) -> 0 | AJ16: =IF($C16=$Z$13,$F16,0) -> 0 | AK16: =IF($C16=$Z$14,$E16,0) -> 0 | AL16: =IF($C16=$Z$14,$F16,0) -> 0 | AM16: =IF($C16=$Z$15,$E16,0) -> 0 | AN16: =IF($C16=$Z$15,$F16,0) -> 0 | AO16: =IF($C16=$Z$16,$E16,0) -> 0 | AP16: =IF($C16=$Z$16,$F16,0) -> 0 | AQ16: =IF($C16=$Z$17,$E16,0) -> 0 | AR16: =IF($C16=$Z$17,$F16,0) -> 0 | AT16: =IF(OR($G16=$AA$11,$G16=$AA$13,($G16=$AA$14),$G16=$AA$15),$AE16+$AG16+$AI16+$AK16+$AQ16,0) -> 0 | AU16: =IF(OR($G16=$AA$11,$G16=$AA$13,($G16=$AA$14),$G16=$AA$15),$AF16+$AH16+$AJ16+AL16+AR16,0) -> 0 | AV16: =IF($G16=$AA$12,$AE16+$AG16+$AI16+AK16+AQ16,0) -> 0 | AW16: =IF($G16=$AA$12,$AF16+$AH16+$AJ16+AL16+AR16,0) -> 0 | AY16: =IF(UPPER($I16) =$AB$12,IF($G16=$AA$12,$AV16,0),0) -> 0 | AZ16: =IF(UPPER($I16) =$AB$12,IF($G16<>$AA$12,$AT16,0),0) -> 0 | BA16: =IF(UPPER($I16) =$AB$12,IF($G16=$AA$12,$AW16,0),0) -> 0 | BB16: =IF(UPPER($I16) =$AB$12,IF($G16<>$AA$12,$AU16,0),0) -> 0 | BC16: =IF(UPPER($J16) =$AB$12,IF($G16=$AA$12,$AV16,0),0) -> 0 | BD16: =IF(UPPER($J16) =$AB$12,IF($G16<>$AA$12,$AT16,0),0) -> 0 | BE16: =IF(UPPER($J16) =$AB$12,IF($G16=$AA$12,$AW16,0),0) -> 0 | BF16: =IF(UPPER($J16) =$AB$12,IF($G16<>$AA$12,$AU16,0),0) -> 0 | BG16: =IF(UPPER($K16) =$AB$12,IF($G16=$AA$12,$AV16,0),0) -> 0 | BH16: =IF(UPPER($K16) =$AB$12,IF($G16<>$AA$12,$AT16,0),0) -> 0 | BI16: =IF(UPPER($K16) =$AB$12,IF($G16=$AA$12,$AW16,0),0) -> 0 | BJ16: =IF(UPPER($K16) =$AB$12,IF($G16<>$AA$12,$AU16,0),0) -> 0 | BL16: =IF(($E16+$F16>0), IF($G16=$AA$10,1,0),0) -> 0 | BM16: =IF(($E16+$F16<=0), IF($G16<>$AA$10,1,0),0) -> 0 | BN16: =IF(($E16+$F16>0), IF($C16=$AA$10,1,0),0) -> 0
A17: 7 | Z17: Prelievo Contante | AE17: =IF($C17=$Z$11,$E17,0) -> 0 | AF17: =IF($C17=$Z$11,$F17,0) -> 0 | AG17: =IF($C17=$Z$12,$E17,0) -> 0 | AH17: =IF($C17=$Z$12,$F17,0) -> 0 | AI17: =IF($C17=$Z$13,$E17,0) -> 0 | AJ17: =IF($C17=$Z$13,$F17,0) -> 0 | AK17: =IF($C17=$Z$14,$E17,0) -> 0 | AL17: =IF($C17=$Z$14,$F17,0) -> 0 | AM17: =IF($C17=$Z$15,$E17,0) -> 0 | AN17: =IF($C17=$Z$15,$F17,0) -> 0 | AO17: =IF($C17=$Z$16,$E17,0) -> 0 | AP17: =IF($C17=$Z$16,$F17,0) -> 0 | AQ17: =IF($C17=$Z$17,$E17,0) -> 0 | AR17: =IF($C17=$Z$17,$F17,0) -> 0 | AT17: =IF(OR($G17=$AA$11,$G17=$AA$13,($G17=$AA$14),$G17=$AA$15),$AE17+$AG17+$AI17+$AK17+$AQ17,0) -> 0 | AU17: =IF(OR($G17=$AA$11,$G17=$AA$13,($G17=$AA$14),$G17=$AA$15),$AF17+$AH17+$AJ17+AL17+AR17,0) -> 0 | AV17: =IF($G17=$AA$12,$AE17+$AG17+$AI17+AK17+AQ17,0) -> 0 | AW17: =IF($G17=$AA$12,$AF17+$AH17+$AJ17+AL17+AR17,0) -> 0 | AY17: =IF(UPPER($I17) =$AB$12,IF($G17=$AA$12,$AV17,0),0) -> 0 | AZ17: =IF(UPPER($I17) =$AB$12,IF($G17<>$AA$12,$AT17,0),0) -> 0 | BA17: =IF(UPPER($I17) =$AB$12,IF($G17=$AA$12,$AW17,0),0) -> 0 | BB17: =IF(UPPER($I17) =$AB$12,IF($G17<>$AA$12,$AU17,0),0) -> 0 | BC17: =IF(UPPER($J17) =$AB$12,IF($G17=$AA$12,$AV17,0),0) -> 0 | BD17: =IF(UPPER($J17) =$AB$12,IF($G17<>$AA$12,$AT17,0),0) -> 0 | BE17: =IF(UPPER($J17) =$AB$12,IF($G17=$AA$12,$AW17,0),0) -> 0 | BF17: =IF(UPPER($J17) =$AB$12,IF($G17<>$AA$12,$AU17,0),0) -> 0 | BG17: =IF(UPPER($K17) =$AB$12,IF($G17=$AA$12,$AV17,0),0) -> 0 | BH17: =IF(UPPER($K17) =$AB$12,IF($G17<>$AA$12,$AT17,0),0) -> 0 | BI17: =IF(UPPER($K17) =$AB$12,IF($G17=$AA$12,$AW17,0),0) -> 0 | BJ17: =IF(UPPER($K17) =$AB$12,IF($G17<>$AA$12,$AU17,0),0) -> 0 | BL17: =IF(($E17+$F17>0), IF($G17=$AA$10,1,0),0) -> 0 | BM17: =IF(($E17+$F17<=0), IF($G17<>$AA$10,1,0),0) -> 0 | BN17: =IF(($E17+$F17>0), IF($C17=$AA$10,1,0),0) -> 0
A18: 8 | AE18: =IF($C18=$Z$11,$E18,0) -> 0 | AF18: =IF($C18=$Z$11,$F18,0) -> 0 | AG18: =IF($C18=$Z$12,$E18,0) -> 0 | AH18: =IF($C18=$Z$12,$F18,0) -> 0 | AI18: =IF($C18=$Z$13,$E18,0) -> 0 | AJ18: =IF($C18=$Z$13,$F18,0) -> 0 | AK18: =IF($C18=$Z$14,$E18,0) -> 0 | AL18: =IF($C18=$Z$14,$F18,0) -> 0 | AM18: =IF($C18=$Z$15,$E18,0) -> 0 | AN18: =IF($C18=$Z$15,$F18,0) -> 0 | AO18: =IF($C18=$Z$16,$E18,0) -> 0 | AP18: =IF($C18=$Z$16,$F18,0) -> 0 | AQ18: =IF($C18=$Z$17,$E18,0) -> 0 | AR18: =IF($C18=$Z$17,$F18,0) -> 0 | AT18: =IF(OR($G18=$AA$11,$G18=$AA$13,($G18=$AA$14),$G18=$AA$15),$AE18+$AG18+$AI18+$AK18+$AQ18,0) -> 0 | AU18: =IF(OR($G18=$AA$11,$G18=$AA$13,($G18=$AA$14),$G18=$AA$15),$AF18+$AH18+$AJ18+AL18+AR18,0) -> 0 | AV18: =IF($G18=$AA$12,$AE18+$AG18+$AI18+AK18+AQ18,0) -> 0 | AW18: =IF($G18=$AA$12,$AF18+$AH18+$AJ18+AL18+AR18,0) -> 0 | AY18: =IF(UPPER($I18) =$AB$12,IF($G18=$AA$12,$AV18,0),0) -> 0 | AZ18: =IF(UPPER($I18) =$AB$12,IF($G18<>$AA$12,$AT18,0),0) -> 0 | BA18: =IF(UPPER($I18) =$AB$12,IF($G18=$AA$12,$AW18,0),0) -> 0 | BB18: =IF(UPPER($I18) =$AB$12,IF($G18<>$AA$12,$AU18,0),0) -> 0 | BC18: =IF(UPPER($J18) =$AB$12,IF($G18=$AA$12,$AV18,0),0) -> 0 | BD18: =IF(UPPER($J18) =$AB$12,IF($G18<>$AA$12,$AT18,0),0) -> 0 | BE18: =IF(UPPER($J18) =$AB$12,IF($G18=$AA$12,$AW18,0),0) -> 0 | BF18: =IF(UPPER($J18) =$AB$12,IF($G18<>$AA$12,$AU18,0),0) -> 0 | BG18: =IF(UPPER($K18) =$AB$12,IF($G18=$AA$12,$AV18,0),0) -> 0 | BH18: =IF(UPPER($K18) =$AB$12,IF($G18<>$AA$12,$AT18,0),0) -> 0 | BI18: =IF(UPPER($K18) =$AB$12,IF($G18=$AA$12,$AW18,0),0) -> 0 | BJ18: =IF(UPPER($K18) =$AB$12,IF($G18<>$AA$12,$AU18,0),0) -> 0 | BL18: =IF(($E18+$F18>0), IF($G18=$AA$10,1,0),0) -> 0 | BM18: =IF(($E18+$F18<=0), IF($G18<>$AA$10,1,0),0) -> 0 | BN18: =IF(($E18+$F18>0), IF($C18=$AA$10,1,0),0) -> 0
A19: 9 | AE19: =IF($C19=$Z$11,$E19,0) -> 0 | AF19: =IF($C19=$Z$11,$F19,0) -> 0 | AG19: =IF($C19=$Z$12,$E19,0) -> 0 | AH19: =IF($C19=$Z$12,$F19,0) -> 0 | AI19: =IF($C19=$Z$13,$E19,0) -> 0 | AJ19: =IF($C19=$Z$13,$F19,0) -> 0 | AK19: =IF($C19=$Z$14,$E19,0) -> 0 | AL19: =IF($C19=$Z$14,$F19,0) -> 0 | AM19: =IF($C19=$Z$15,$E19,0) -> 0 | AN19: =IF($C19=$Z$15,$F19,0) -> 0 | AO19: =IF($C19=$Z$16,$E19,0) -> 0 | AP19: =IF($C19=$Z$16,$F19,0) -> 0 | AQ19: =IF($C19=$Z$17,$E19,0) -> 0 | AR19: =IF($C19=$Z$17,$F19,0) -> 0 | AT19: =IF(OR($G19=$AA$11,$G19=$AA$13,($G19=$AA$14),$G19=$AA$15),$AE19+$AG19+$AI19+$AK19+$AQ19,0) -> 0 | AU19: =IF(OR($G19=$AA$11,$G19=$AA$13,($G19=$AA$14),$G19=$AA$15),$AF19+$AH19+$AJ19+AL19+AR19,0) -> 0 | AV19: =IF($G19=$AA$12,$AE19+$AG19+$AI19+AK19+AQ19,0) -> 0 | AW19: =IF($G19=$AA$12,$AF19+$AH19+$AJ19+AL19+AR19,0) -> 0 | AY19: =IF(UPPER($I19) =$AB$12,IF($G19=$AA$12,$AV19,0),0) -> 0 | AZ19: =IF(UPPER($I19) =$AB$12,IF($G19<>$AA$12,$AT19,0),0) -> 0 | BA19: =IF(UPPER($I19) =$AB$12,IF($G19=$AA$12,$AW19,0),0) -> 0 | BB19: =IF(UPPER($I19) =$AB$12,IF($G19<>$AA$12,$AU19,0),0) -> 0 | BC19: =IF(UPPER($J19) =$AB$12,IF($G19=$AA$12,$AV19,0),0) -> 0 | BD19: =IF(UPPER($J19) =$AB$12,IF($G19<>$AA$12,$AT19,0),0) -> 0 | BE19: =IF(UPPER($J19) =$AB$12,IF($G19=$AA$12,$AW19,0),0) -> 0 | BF19: =IF(UPPER($J19) =$AB$12,IF($G19<>$AA$12,$AU19,0),0) -> 0 | BG19: =IF(UPPER($K19) =$AB$12,IF($G19=$AA$12,$AV19,0),0) -> 0 | BH19: =IF(UPPER($K19) =$AB$12,IF($G19<>$AA$12,$AT19,0),0) -> 0 | BI19: =IF(UPPER($K19) =$AB$12,IF($G19=$AA$12,$AW19,0),0) -> 0 | BJ19: =IF(UPPER($K19) =$AB$12,IF($G19<>$AA$12,$AU19,0),0) -> 0 | BL19: =IF(($E19+$F19>0), IF($G19=$AA$10,1,0),0) -> 0 | BM19: =IF(($E19+$F19<=0), IF($G19<>$AA$10,1,0),0) -> 0 | BN19: =IF(($E19+$F19>0), IF($C19=$AA$10,1,0),0) -> 0
A20: 10 | AE20: =IF($C20=$Z$11,$E20,0) -> 0 | AF20: =IF($C20=$Z$11,$F20,0) -> 0 | AG20: =IF($C20=$Z$12,$E20,0) -> 0 | AH20: =IF($C20=$Z$12,$F20,0) -> 0 | AI20: =IF($C20=$Z$13,$E20,0) -> 0 | AJ20: =IF($C20=$Z$13,$F20,0) -> 0 | AK20: =IF($C20=$Z$14,$E20,0) -> 0 | AL20: =IF($C20=$Z$14,$F20,0) -> 0 | AM20: =IF($C20=$Z$15,$E20,0) -> 0 | AN20: =IF($C20=$Z$15,$F20,0) -> 0 | AO20: =IF($C20=$Z$16,$E20,0) -> 0 | AP20: =IF($C20=$Z$16,$F20,0) -> 0 | AQ20: =IF($C20=$Z$17,$E20,0) -> 0 | AR20: =IF($C20=$Z$17,$F20,0) -> 0 | AT20: =IF(OR($G20=$AA$11,$G20=$AA$13,($G20=$AA$14),$G20=$AA$15),$AE20+$AG20+$AI20+$AK20+$AQ20,0) -> 0 | AU20: =IF(OR($G20=$AA$11,$G20=$AA$13,($G20=$AA$14),$G20=$AA$15),$AF20+$AH20+$AJ20+AL20+AR20,0) -> 0 | AV20: =IF($G20=$AA$12,$AE20+$AG20+$AI20+AK20+AQ20,0) -> 0 | AW20: =IF($G20=$AA$12,$AF20+$AH20+$AJ20+AL20+AR20,0) -> 0 | AY20: =IF(UPPER($I20) =$AB$12,IF($G20=$AA$12,$AV20,0),0) -> 0 | AZ20: =IF(UPPER($I20) =$AB$12,IF($G20<>$AA$12,$AT20,0),0) -> 0 | BA20: =IF(UPPER($I20) =$AB$12,IF($G20=$AA$12,$AW20,0),0) -> 0 | BB20: =IF(UPPER($I20) =$AB$12,IF($G20<>$AA$12,$AU20,0),0) -> 0 | BC20: =IF(UPPER($J20) =$AB$12,IF($G20=$AA$12,$AV20,0),0) -> 0 | BD20: =IF(UPPER($J20) =$AB$12,IF($G20<>$AA$12,$AT20,0),0) -> 0 | BE20: =IF(UPPER($J20) =$AB$12,IF($G20=$AA$12,$AW20,0),0) -> 0 | BF20: =IF(UPPER($J20) =$AB$12,IF($G20<>$AA$12,$AU20,0),0) -> 0 | BG20: =IF(UPPER($K20) =$AB$12,IF($G20=$AA$12,$AV20,0),0) -> 0 | BH20: =IF(UPPER($K20) =$AB$12,IF($G20<>$AA$12,$AT20,0),0) -> 0 | BI20: =IF(UPPER($K20) =$AB$12,IF($G20=$AA$12,$AW20,0),0) -> 0 | BJ20: =IF(UPPER($K20) =$AB$12,IF($G20<>$AA$12,$AU20,0),0) -> 0 | BL20: =IF(($E20+$F20>0), IF($G20=$AA$10,1,0),0) -> 0 | BM20: =IF(($E20+$F20<=0), IF($G20<>$AA$10,1,0),0) -> 0 | BN20: =IF(($E20+$F20>0), IF($C20=$AA$10,1,0),0) -> 0
A21: 11 | AE21: =IF($C21=$Z$11,$E21,0) -> 0 | AF21: =IF($C21=$Z$11,$F21,0) -> 0 | AG21: =IF($C21=$Z$12,$E21,0) -> 0 | AH21: =IF($C21=$Z$12,$F21,0) -> 0 | AI21: =IF($C21=$Z$13,$E21,0) -> 0 | AJ21: =IF($C21=$Z$13,$F21,0) -> 0 | AK21: =IF($C21=$Z$14,$E21,0) -> 0 | AL21: =IF($C21=$Z$14,$F21,0) -> 0 | AM21: =IF($C21=$Z$15,$E21,0) -> 0 | AN21: =IF($C21=$Z$15,$F21,0) -> 0 | AO21: =IF($C21=$Z$16,$E21,0) -> 0 | AP21: =IF($C21=$Z$16,$F21,0) -> 0 | AQ21: =IF($C21=$Z$17,$E21,0) -> 0 | AR21: =IF($C21=$Z$17,$F21,0) -> 0 | AT21: =IF(OR($G21=$AA$11,$G21=$AA$13,($G21=$AA$14),$G21=$AA$15),$AE21+$AG21+$AI21+$AK21+$AQ21,0) -> 0 | AU21: =IF(OR($G21=$AA$11,$G21=$AA$13,($G21=$AA$14),$G21=$AA$15),$AF21+$AH21+$AJ21+AL21+AR21,0) -> 0 | AV21: =IF($G21=$AA$12,$AE21+$AG21+$AI21+AK21+AQ21,0) -> 0 | AW21: =IF($G21=$AA$12,$AF21+$AH21+$AJ21+AL21+AR21,0) -> 0 | AY21: =IF(UPPER($I21) =$AB$12,IF($G21=$AA$12,$AV21,0),0) -> 0 | AZ21: =IF(UPPER($I21) =$AB$12,IF($G21<>$AA$12,$AT21,0),0) -> 0 | BA21: =IF(UPPER($I21) =$AB$12,IF($G21=$AA$12,$AW21,0),0) -> 0 | BB21: =IF(UPPER($I21) =$AB$12,IF($G21<>$AA$12,$AU21,0),0) -> 0 | BC21: =IF(UPPER($J21) =$AB$12,IF($G21=$AA$12,$AV21,0),0) -> 0 | BD21: =IF(UPPER($J21) =$AB$12,IF($G21<>$AA$12,$AT21,0),0) -> 0 | BE21: =IF(UPPER($J21) =$AB$12,IF($G21=$AA$12,$AW21,0),0) -> 0 | BF21: =IF(UPPER($J21) =$AB$12,IF($G21<>$AA$12,$AU21,0),0) -> 0 | BG21: =IF(UPPER($K21) =$AB$12,IF($G21=$AA$12,$AV21,0),0) -> 0 | BH21: =IF(UPPER($K21) =$AB$12,IF($G21<>$AA$12,$AT21,0),0) -> 0 | BI21: =IF(UPPER($K21) =$AB$12,IF($G21=$AA$12,$AW21,0),0) -> 0 | BJ21: =IF(UPPER($K21) =$AB$12,IF($G21<>$AA$12,$AU21,0),0) -> 0 | BL21: =IF(($E21+$F21>0), IF($G21=$AA$10,1,0),0) -> 0 | BM21: =IF(($E21+$F21<=0), IF($G21<>$AA$10,1,0),0) -> 0 | BN21: =IF(($E21+$F21>0), IF($C21=$AA$10,1,0),0) -> 0
A22: 12 | AE22: =IF($C22=$Z$11,$E22,0) -> 0 | AF22: =IF($C22=$Z$11,$F22,0) -> 0 | AG22: =IF($C22=$Z$12,$E22,0) -> 0 | AH22: =IF($C22=$Z$12,$F22,0) -> 0 | AI22: =IF($C22=$Z$13,$E22,0) -> 0 | AJ22: =IF($C22=$Z$13,$F22,0) -> 0 | AK22: =IF($C22=$Z$14,$E22,0) -> 0 | AL22: =IF($C22=$Z$14,$F22,0) -> 0 | AM22: =IF($C22=$Z$15,$E22,0) -> 0 | AN22: =IF($C22=$Z$15,$F22,0) -> 0 | AO22: =IF($C22=$Z$16,$E22,0) -> 0 | AP22: =IF($C22=$Z$16,$F22,0) -> 0 | AQ22: =IF($C22=$Z$17,$E22,0) -> 0 | AR22: =IF($C22=$Z$17,$F22,0) -> 0 | AT22: =IF(OR($G22=$AA$11,$G22=$AA$13,($G22=$AA$14),$G22=$AA$15),$AE22+$AG22+$AI22+$AK22+$AQ22,0) -> 0 | AU22: =IF(OR($G22=$AA$11,$G22=$AA$13,($G22=$AA$14),$G22=$AA$15),$AF22+$AH22+$AJ22+AL22+AR22,0) -> 0 | AV22: =IF($G22=$AA$12,$AE22+$AG22+$AI22+AK22+AQ22,0) -> 0 | AW22: =IF($G22=$AA$12,$AF22+$AH22+$AJ22+AL22+AR22,0) -> 0 | AY22: =IF(UPPER($I22) =$AB$12,IF($G22=$AA$12,$AV22,0),0) -> 0 | AZ22: =IF(UPPER($I22) =$AB$12,IF($G22<>$AA$12,$AT22,0),0) -> 0 | BA22: =IF(UPPER($I22) =$AB$12,IF($G22=$AA$12,$AW22,0),0) -> 0 | BB22: =IF(UPPER($I22) =$AB$12,IF($G22<>$AA$12,$AU22,0),0) -> 0 | BC22: =IF(UPPER($J22) =$AB$12,IF($G22=$AA$12,$AV22,0),0) -> 0 | BD22: =IF(UPPER($J22) =$AB$12,IF($G22<>$AA$12,$AT22,0),0) -> 0 | BE22: =IF(UPPER($J22) =$AB$12,IF($G22=$AA$12,$AW22,0),0) -> 0 | BF22: =IF(UPPER($J22) =$AB$12,IF($G22<>$AA$12,$AU22,0),0) -> 0 | BG22: =IF(UPPER($K22) =$AB$12,IF($G22=$AA$12,$AV22,0),0) -> 0 | BH22: =IF(UPPER($K22) =$AB$12,IF($G22<>$AA$12,$AT22,0),0) -> 0 | BI22: =IF(UPPER($K22) =$AB$12,IF($G22=$AA$12,$AW22,0),0) -> 0 | BJ22: =IF(UPPER($K22) =$AB$12,IF($G22<>$AA$12,$AU22,0),0) -> 0 | BL22: =IF(($E22+$F22>0), IF($G22=$AA$10,1,0),0) -> 0 | BM22: =IF(($E22+$F22<=0), IF($G22<>$AA$10,1,0),0) -> 0 | BN22: =IF(($E22+$F22>0), IF($C22=$AA$10,1,0),0) -> 0
A23: 13 | AE23: =IF($C23=$Z$11,$E23,0) -> 0 | AF23: =IF($C23=$Z$11,$F23,0) -> 0 | AG23: =IF($C23=$Z$12,$E23,0) -> 0 | AH23: =IF($C23=$Z$12,$F23,0) -> 0 | AI23: =IF($C23=$Z$13,$E23,0) -> 0 | AJ23: =IF($C23=$Z$13,$F23,0) -> 0 | AK23: =IF($C23=$Z$14,$E23,0) -> 0 | AL23: =IF($C23=$Z$14,$F23,0) -> 0 | AM23: =IF($C23=$Z$15,$E23,0) -> 0 | AN23: =IF($C23=$Z$15,$F23,0) -> 0 | AO23: =IF($C23=$Z$16,$E23,0) -> 0 | AP23: =IF($C23=$Z$16,$F23,0) -> 0 | AQ23: =IF($C23=$Z$17,$E23,0) -> 0 | AR23: =IF($C23=$Z$17,$F23,0) -> 0 | AT23: =IF(OR($G23=$AA$11,$G23=$AA$13,($G23=$AA$14),$G23=$AA$15),$AE23+$AG23+$AI23+$AK23+$AQ23,0) -> 0 | AU23: =IF(OR($G23=$AA$11,$G23=$AA$13,($G23=$AA$14),$G23=$AA$15),$AF23+$AH23+$AJ23+AL23+AR23,0) -> 0 | AV23: =IF($G23=$AA$12,$AE23+$AG23+$AI23+AK23+AQ23,0) -> 0 | AW23: =IF($G23=$AA$12,$AF23+$AH23+$AJ23+AL23+AR23,0) -> 0 | AY23: =IF(UPPER($I23) =$AB$12,IF($G23=$AA$12,$AV23,0),0) -> 0 | AZ23: =IF(UPPER($I23) =$AB$12,IF($G23<>$AA$12,$AT23,0),0) -> 0 | BA23: =IF(UPPER($I23) =$AB$12,IF($G23=$AA$12,$AW23,0),0) -> 0 | BB23: =IF(UPPER($I23) =$AB$12,IF($G23<>$AA$12,$AU23,0),0) -> 0 | BC23: =IF(UPPER($J23) =$AB$12,IF($G23=$AA$12,$AV23,0),0) -> 0 | BD23: =IF(UPPER($J23) =$AB$12,IF($G23<>$AA$12,$AT23,0),0) -> 0 | BE23: =IF(UPPER($J23) =$AB$12,IF($G23=$AA$12,$AW23,0),0) -> 0 | BF23: =IF(UPPER($J23) =$AB$12,IF($G23<>$AA$12,$AU23,0),0) -> 0 | BG23: =IF(UPPER($K23) =$AB$12,IF($G23=$AA$12,$AV23,0),0) -> 0 | BH23: =IF(UPPER($K23) =$AB$12,IF($G23<>$AA$12,$AT23,0),0) -> 0 | BI23: =IF(UPPER($K23) =$AB$12,IF($G23=$AA$12,$AW23,0),0) -> 0 | BJ23: =IF(UPPER($K23) =$AB$12,IF($G23<>$AA$12,$AU23,0),0) -> 0 | BL23: =IF(($E23+$F23>0), IF($G23=$AA$10,1,0),0) -> 0 | BM23: =IF(($E23+$F23<=0), IF($G23<>$AA$10,1,0),0) -> 0 | BN23: =IF(($E23+$F23>0), IF($C23=$AA$10,1,0),0) -> 0
A24: 14 | AE24: =IF($C24=$Z$11,$E24,0) -> 0 | AF24: =IF($C24=$Z$11,$F24,0) -> 0 | AG24: =IF($C24=$Z$12,$E24,0) -> 0 | AH24: =IF($C24=$Z$12,$F24,0) -> 0 | AI24: =IF($C24=$Z$13,$E24,0) -> 0 | AJ24: =IF($C24=$Z$13,$F24,0) -> 0 | AK24: =IF($C24=$Z$14,$E24,0) -> 0 | AL24: =IF($C24=$Z$14,$F24,0) -> 0 | AM24: =IF($C24=$Z$15,$E24,0) -> 0 | AN24: =IF($C24=$Z$15,$F24,0) -> 0 | AO24: =IF($C24=$Z$16,$E24,0) -> 0 | AP24: =IF($C24=$Z$16,$F24,0) -> 0 | AQ24: =IF($C24=$Z$17,$E24,0) -> 0 | AR24: =IF($C24=$Z$17,$F24,0) -> 0 | AT24: =IF(OR($G24=$AA$11,$G24=$AA$13,($G24=$AA$14),$G24=$AA$15),$AE24+$AG24+$AI24+$AK24+$AQ24,0) -> 0 | AU24: =IF(OR($G24=$AA$11,$G24=$AA$13,($G24=$AA$14),$G24=$AA$15),$AF24+$AH24+$AJ24+AL24+AR24,0) -> 0 | AV24: =IF($G24=$AA$12,$AE24+$AG24+$AI24+AK24+AQ24,0) -> 0 | AW24: =IF($G24=$AA$12,$AF24+$AH24+$AJ24+AL24+AR24,0) -> 0 | AY24: =IF(UPPER($I24) =$AB$12,IF($G24=$AA$12,$AV24,0),0) -> 0 | AZ24: =IF(UPPER($I24) =$AB$12,IF($G24<>$AA$12,$AT24,0),0) -> 0 | BA24: =IF(UPPER($I24) =$AB$12,IF($G24=$AA$12,$AW24,0),0) -> 0 | BB24: =IF(UPPER($I24) =$AB$12,IF($G24<>$AA$12,$AU24,0),0) -> 0 | BC24: =IF(UPPER($J24) =$AB$12,IF($G24=$AA$12,$AV24,0),0) -> 0 | BD24: =IF(UPPER($J24) =$AB$12,IF($G24<>$AA$12,$AT24,0),0) -> 0 | BE24: =IF(UPPER($J24) =$AB$12,IF($G24=$AA$12,$AW24,0),0) -> 0 | BF24: =IF(UPPER($J24) =$AB$12,IF($G24<>$AA$12,$AU24,0),0) -> 0 | BG24: =IF(UPPER($K24) =$AB$12,IF($G24=$AA$12,$AV24,0),0) -> 0 | BH24: =IF(UPPER($K24) =$AB$12,IF($G24<>$AA$12,$AT24,0),0) -> 0 | BI24: =IF(UPPER($K24) =$AB$12,IF($G24=$AA$12,$AW24,0),0) -> 0 | BJ24: =IF(UPPER($K24) =$AB$12,IF($G24<>$AA$12,$AU24,0),0) -> 0 | BL24: =IF(($E24+$F24>0), IF($G24=$AA$10,1,0),0) -> 0 | BM24: =IF(($E24+$F24<=0), IF($G24<>$AA$10,1,0),0) -> 0 | BN24: =IF(($E24+$F24>0), IF($C24=$AA$10,1,0),0) -> 0
A25: 15 | AE25: =IF($C25=$Z$11,$E25,0) -> 0 | AF25: =IF($C25=$Z$11,$F25,0) -> 0 | AG25: =IF($C25=$Z$12,$E25,0) -> 0 | AH25: =IF($C25=$Z$12,$F25,0) -> 0 | AI25: =IF($C25=$Z$13,$E25,0) -> 0 | AJ25: =IF($C25=$Z$13,$F25,0) -> 0 | AK25: =IF($C25=$Z$14,$E25,0) -> 0 | AL25: =IF($C25=$Z$14,$F25,0) -> 0 | AM25: =IF($C25=$Z$15,$E25,0) -> 0 | AN25: =IF($C25=$Z$15,$F25,0) -> 0 | AO25: =IF($C25=$Z$16,$E25,0) -> 0 | AP25: =IF($C25=$Z$16,$F25,0) -> 0 | AQ25: =IF($C25=$Z$17,$E25,0) -> 0 | AR25: =IF($C25=$Z$17,$F25,0) -> 0 | AT25: =IF(OR($G25=$AA$11,$G25=$AA$13,($G25=$AA$14),$G25=$AA$15),$AE25+$AG25+$AI25+$AK25+$AQ25,0) -> 0 | AU25: =IF(OR($G25=$AA$11,$G25=$AA$13,($G25=$AA$14),$G25=$AA$15),$AF25+$AH25+$AJ25+AL25+AR25,0) -> 0 | AV25: =IF($G25=$AA$12,$AE25+$AG25+$AI25+AK25+AQ25,0) -> 0 | AW25: =IF($G25=$AA$12,$AF25+$AH25+$AJ25+AL25+AR25,0) -> 0 | AY25: =IF(UPPER($I25) =$AB$12,IF($G25=$AA$12,$AV25,0),0) -> 0 | AZ25: =IF(UPPER($I25) =$AB$12,IF($G25<>$AA$12,$AT25,0),0) -> 0 | BA25: =IF(UPPER($I25) =$AB$12,IF($G25=$AA$12,$AW25,0),0) -> 0 | BB25: =IF(UPPER($I25) =$AB$12,IF($G25<>$AA$12,$AU25,0),0) -> 0 | BC25: =IF(UPPER($J25) =$AB$12,IF($G25=$AA$12,$AV25,0),0) -> 0 | BD25: =IF(UPPER($J25) =$AB$12,IF($G25<>$AA$12,$AT25,0),0) -> 0 | BE25: =IF(UPPER($J25) =$AB$12,IF($G25=$AA$12,$AW25,0),0) -> 0 | BF25: =IF(UPPER($J25) =$AB$12,IF($G25<>$AA$12,$AU25,0),0) -> 0 | BG25: =IF(UPPER($K25) =$AB$12,IF($G25=$AA$12,$AV25,0),0) -> 0 | BH25: =IF(UPPER($K25) =$AB$12,IF($G25<>$AA$12,$AT25,0),0) -> 0 | BI25: =IF(UPPER($K25) =$AB$12,IF($G25=$AA$12,$AW25,0),0) -> 0 | BJ25: =IF(UPPER($K25) =$AB$12,IF($G25<>$AA$12,$AU25,0),0) -> 0 | BL25: =IF(($E25+$F25>0), IF($G25=$AA$10,1,0),0) -> 0 | BM25: =IF(($E25+$F25<=0), IF($G25<>$AA$10,1,0),0) -> 0 | BN25: =IF(($E25+$F25>0), IF($C25=$AA$10,1,0),0) -> 0
A26: 16 | AE26: =IF($C26=$Z$11,$E26,0) -> 0 | AF26: =IF($C26=$Z$11,$F26,0) -> 0 | AG26: =IF($C26=$Z$12,$E26,0) -> 0 | AH26: =IF($C26=$Z$12,$F26,0) -> 0 | AI26: =IF($C26=$Z$13,$E26,0) -> 0 | AJ26: =IF($C26=$Z$13,$F26,0) -> 0 | AK26: =IF($C26=$Z$14,$E26,0) -> 0 | AL26: =IF($C26=$Z$14,$F26,0) -> 0 | AM26: =IF($C26=$Z$15,$E26,0) -> 0 | AN26: =IF($C26=$Z$15,$F26,0) -> 0 | AO26: =IF($C26=$Z$16,$E26,0) -> 0 | AP26: =IF($C26=$Z$16,$F26,0) -> 0 | AQ26: =IF($C26=$Z$17,$E26,0) -> 0 | AR26: =IF($C26=$Z$17,$F26,0) -> 0 | AT26: =IF(OR($G26=$AA$11,$G26=$AA$13,($G26=$AA$14),$G26=$AA$15),$AE26+$AG26+$AI26+$AK26+$AQ26,0) -> 0 | AU26: =IF(OR($G26=$AA$11,$G26=$AA$13,($G26=$AA$14),$G26=$AA$15),$AF26+$AH26+$AJ26+AL26+AR26,0) -> 0 | AV26: =IF($G26=$AA$12,$AE26+$AG26+$AI26+AK26+AQ26,0) -> 0 | AW26: =IF($G26=$AA$12,$AF26+$AH26+$AJ26+AL26+AR26,0) -> 0 | AY26: =IF(UPPER($I26) =$AB$12,IF($G26=$AA$12,$AV26,0),0) -> 0 | AZ26: =IF(UPPER($I26) =$AB$12,IF($G26<>$AA$12,$AT26,0),0) -> 0 | BA26: =IF(UPPER($I26) =$AB$12,IF($G26=$AA$12,$AW26,0),0) -> 0 | BB26: =IF(UPPER($I26) =$AB$12,IF($G26<>$AA$12,$AU26,0),0) -> 0 | BC26: =IF(UPPER($J26) =$AB$12,IF($G26=$AA$12,$AV26,0),0) -> 0 | BD26: =IF(UPPER($J26) =$AB$12,IF($G26<>$AA$12,$AT26,0),0) -> 0 | BE26: =IF(UPPER($J26) =$AB$12,IF($G26=$AA$12,$AW26,0),0) -> 0 | BF26: =IF(UPPER($J26) =$AB$12,IF($G26<>$AA$12,$AU26,0),0) -> 0 | BG26: =IF(UPPER($K26) =$AB$12,IF($G26=$AA$12,$AV26,0),0) -> 0 | BH26: =IF(UPPER($K26) =$AB$12,IF($G26<>$AA$12,$AT26,0),0) -> 0 | BI26: =IF(UPPER($K26) =$AB$12,IF($G26=$AA$12,$AW26,0),0) -> 0 | BJ26: =IF(UPPER($K26) =$AB$12,IF($G26<>$AA$12,$AU26,0),0) -> 0 | BL26: =IF(($E26+$F26>0), IF($G26=$AA$10,1,0),0) -> 0 | BM26: =IF(($E26+$F26<=0), IF($G26<>$AA$10,1,0),0) -> 0 | BN26: =IF(($E26+$F26>0), IF($C26=$AA$10,1,0),0) -> 0
A27: 17 | AE27: =IF($C27=$Z$11,$E27,0) -> 0 | AF27: =IF($C27=$Z$11,$F27,0) -> 0 | AG27: =IF($C27=$Z$12,$E27,0) -> 0 | AH27: =IF($C27=$Z$12,$F27,0) -> 0 | AI27: =IF($C27=$Z$13,$E27,0) -> 0 | AJ27: =IF($C27=$Z$13,$F27,0) -> 0 | AK27: =IF($C27=$Z$14,$E27,0) -> 0 | AL27: =IF($C27=$Z$14,$F27,0) -> 0 | AM27: =IF($C27=$Z$15,$E27,0) -> 0 | AN27: =IF($C27=$Z$15,$F27,0) -> 0 | AO27: =IF($C27=$Z$16,$E27,0) -> 0 | AP27: =IF($C27=$Z$16,$F27,0) -> 0 | AQ27: =IF($C27=$Z$17,$E27,0) -> 0 | AR27: =IF($C27=$Z$17,$F27,0) -> 0 | AT27: =IF(OR($G27=$AA$11,$G27=$AA$13,($G27=$AA$14),$G27=$AA$15),$AE27+$AG27+$AI27+$AK27+$AQ27,0) -> 0 | AU27: =IF(OR($G27=$AA$11,$G27=$AA$13,($G27=$AA$14),$G27=$AA$15),$AF27+$AH27+$AJ27+AL27+AR27,0) -> 0 | AV27: =IF($G27=$AA$12,$AE27+$AG27+$AI27+AK27+AQ27,0) -> 0 | AW27: =IF($G27=$AA$12,$AF27+$AH27+$AJ27+AL27+AR27,0) -> 0 | AY27: =IF(UPPER($I27) =$AB$12,IF($G27=$AA$12,$AV27,0),0) -> 0 | AZ27: =IF(UPPER($I27) =$AB$12,IF($G27<>$AA$12,$AT27,0),0) -> 0 | BA27: =IF(UPPER($I27) =$AB$12,IF($G27=$AA$12,$AW27,0),0) -> 0 | BB27: =IF(UPPER($I27) =$AB$12,IF($G27<>$AA$12,$AU27,0),0) -> 0 | BC27: =IF(UPPER($J27) =$AB$12,IF($G27=$AA$12,$AV27,0),0) -> 0 | BD27: =IF(UPPER($J27) =$AB$12,IF($G27<>$AA$12,$AT27,0),0) -> 0 | BE27: =IF(UPPER($J27) =$AB$12,IF($G27=$AA$12,$AW27,0),0) -> 0 | BF27: =IF(UPPER($J27) =$AB$12,IF($G27<>$AA$12,$AU27,0),0) -> 0 | BG27: =IF(UPPER($K27) =$AB$12,IF($G27=$AA$12,$AV27,0),0) -> 0 | BH27: =IF(UPPER($K27) =$AB$12,IF($G27<>$AA$12,$AT27,0),0) -> 0 | BI27: =IF(UPPER($K27) =$AB$12,IF($G27=$AA$12,$AW27,0),0) -> 0 | BJ27: =IF(UPPER($K27) =$AB$12,IF($G27<>$AA$12,$AU27,0),0) -> 0 | BL27: =IF(($E27+$F27>0), IF($G27=$AA$10,1,0),0) -> 0 | BM27: =IF(($E27+$F27<=0), IF($G27<>$AA$10,1,0),0) -> 0 | BN27: =IF(($E27+$F27>0), IF($C27=$AA$10,1,0),0) -> 0
A28: 18 | AE28: =IF($C28=$Z$11,$E28,0) -> 0 | AF28: =IF($C28=$Z$11,$F28,0) -> 0 | AG28: =IF($C28=$Z$12,$E28,0) -> 0 | AH28: =IF($C28=$Z$12,$F28,0) -> 0 | AI28: =IF($C28=$Z$13,$E28,0) -> 0 | AJ28: =IF($C28=$Z$13,$F28,0) -> 0 | AK28: =IF($C28=$Z$14,$E28,0) -> 0 | AL28: =IF($C28=$Z$14,$F28,0) -> 0 | AM28: =IF($C28=$Z$15,$E28,0) -> 0 | AN28: =IF($C28=$Z$15,$F28,0) -> 0 | AO28: =IF($C28=$Z$16,$E28,0) -> 0 | AP28: =IF($C28=$Z$16,$F28,0) -> 0 | AQ28: =IF($C28=$Z$17,$E28,0) -> 0 | AR28: =IF($C28=$Z$17,$F28,0) -> 0 | AT28: =IF(OR($G28=$AA$11,$G28=$AA$13,($G28=$AA$14),$G28=$AA$15),$AE28+$AG28+$AI28+$AK28+$AQ28,0) -> 0 | AU28: =IF(OR($G28=$AA$11,$G28=$AA$13,($G28=$AA$14),$G28=$AA$15),$AF28+$AH28+$AJ28+AL28+AR28,0) -> 0 | AV28: =IF($G28=$AA$12,$AE28+$AG28+$AI28+AK28+AQ28,0) -> 0 | AW28: =IF($G28=$AA$12,$AF28+$AH28+$AJ28+AL28+AR28,0) -> 0 | AY28: =IF(UPPER($I28) =$AB$12,IF($G28=$AA$12,$AV28,0),0) -> 0 | AZ28: =IF(UPPER($I28) =$AB$12,IF($G28<>$AA$12,$AT28,0),0) -> 0 | BA28: =IF(UPPER($I28) =$AB$12,IF($G28=$AA$12,$AW28,0),0) -> 0 | BB28: =IF(UPPER($I28) =$AB$12,IF($G28<>$AA$12,$AU28,0),0) -> 0 | BC28: =IF(UPPER($J28) =$AB$12,IF($G28=$AA$12,$AV28,0),0) -> 0 | BD28: =IF(UPPER($J28) =$AB$12,IF($G28<>$AA$12,$AT28,0),0) -> 0 | BE28: =IF(UPPER($J28) =$AB$12,IF($G28=$AA$12,$AW28,0),0) -> 0 | BF28: =IF(UPPER($J28) =$AB$12,IF($G28<>$AA$12,$AU28,0),0) -> 0 | BG28: =IF(UPPER($K28) =$AB$12,IF($G28=$AA$12,$AV28,0),0) -> 0 | BH28: =IF(UPPER($K28) =$AB$12,IF($G28<>$AA$12,$AT28,0),0) -> 0 | BI28: =IF(UPPER($K28) =$AB$12,IF($G28=$AA$12,$AW28,0),0) -> 0 | BJ28: =IF(UPPER($K28) =$AB$12,IF($G28<>$AA$12,$AU28,0),0) -> 0 | BL28: =IF(($E28+$F28>0), IF($G28=$AA$10,1,0),0) -> 0 | BM28: =IF(($E28+$F28<=0), IF($G28<>$AA$10,1,0),0) -> 0 | BN28: =IF(($E28+$F28>0), IF($C28=$AA$10,1,0),0) -> 0
A29: 19 | AE29: =IF($C29=$Z$11,$E29,0) -> 0 | AF29: =IF($C29=$Z$11,$F29,0) -> 0 | AG29: =IF($C29=$Z$12,$E29,0) -> 0 | AH29: =IF($C29=$Z$12,$F29,0) -> 0 | AI29: =IF($C29=$Z$13,$E29,0) -> 0 | AJ29: =IF($C29=$Z$13,$F29,0) -> 0 | AK29: =IF($C29=$Z$14,$E29,0) -> 0 | AL29: =IF($C29=$Z$14,$F29,0) -> 0 | AM29: =IF($C29=$Z$15,$E29,0) -> 0 | AN29: =IF($C29=$Z$15,$F29,0) -> 0 | AO29: =IF($C29=$Z$16,$E29,0) -> 0 | AP29: =IF($C29=$Z$16,$F29,0) -> 0 | AQ29: =IF($C29=$Z$17,$E29,0) -> 0 | AR29: =IF($C29=$Z$17,$F29,0) -> 0 | AT29: =IF(OR($G29=$AA$11,$G29=$AA$13,($G29=$AA$14),$G29=$AA$15),$AE29+$AG29+$AI29+$AK29+$AQ29,0) -> 0 | AU29: =IF(OR($G29=$AA$11,$G29=$AA$13,($G29=$AA$14),$G29=$AA$15),$AF29+$AH29+$AJ29+AL29+AR29,0) -> 0 | AV29: =IF($G29=$AA$12,$AE29+$AG29+$AI29+AK29+AQ29,0) -> 0 | AW29: =IF($G29=$AA$12,$AF29+$AH29+$AJ29+AL29+AR29,0) -> 0 | AY29: =IF(UPPER($I29) =$AB$12,IF($G29=$AA$12,$AV29,0),0) -> 0 | AZ29: =IF(UPPER($I29) =$AB$12,IF($G29<>$AA$12,$AT29,0),0) -> 0 | BA29: =IF(UPPER($I29) =$AB$12,IF($G29=$AA$12,$AW29,0),0) -> 0 | BB29: =IF(UPPER($I29) =$AB$12,IF($G29<>$AA$12,$AU29,0),0) -> 0 | BC29: =IF(UPPER($J29) =$AB$12,IF($G29=$AA$12,$AV29,0),0) -> 0 | BD29: =IF(UPPER($J29) =$AB$12,IF($G29<>$AA$12,$AT29,0),0) -> 0 | BE29: =IF(UPPER($J29) =$AB$12,IF($G29=$AA$12,$AW29,0),0) -> 0 | BF29: =IF(UPPER($J29) =$AB$12,IF($G29<>$AA$12,$AU29,0),0) -> 0 | BG29: =IF(UPPER($K29) =$AB$12,IF($G29=$AA$12,$AV29,0),0) -> 0 | BH29: =IF(UPPER($K29) =$AB$12,IF($G29<>$AA$12,$AT29,0),0) -> 0 | BI29: =IF(UPPER($K29) =$AB$12,IF($G29=$AA$12,$AW29,0),0) -> 0 | BJ29: =IF(UPPER($K29) =$AB$12,IF($G29<>$AA$12,$AU29,0),0) -> 0 | BL29: =IF(($E29+$F29>0), IF($G29=$AA$10,1,0),0) -> 0 | BM29: =IF(($E29+$F29<=0), IF($G29<>$AA$10,1,0),0) -> 0 | BN29: =IF(($E29+$F29>0), IF($C29=$AA$10,1,0),0) -> 0
... A34: 24 | AE34: =IF($C34=$Z$11,$E34,0) -> 0 | AF34: =IF($C34=$Z$11,$F34,0) -> 0 | AG34: =IF($C34=$Z$12,$E34,0) -> 0 | AH34: =IF($C34=$Z$12,$F34,0) -> 0 | AI34: =IF($C34=$Z$13,$E34,0) -> 0 | AJ34: =IF($C34=$Z$13,$F34,0) -> 0 | AK34: =IF($C34=$Z$14,$E34,0) -> 0 | AL34: =IF($C34=$Z$14,$F34,0) -> 0 | AM34: =IF($C34=$Z$15,$E34,0) -> 0 | AN34: =IF($C34=$Z$15,$F34,0) -> 0 | AO34: =IF($C34=$Z$16,$E34,0) -> 0 | AP34: =IF($C34=$Z$16,$F34,0) -> 0 | AQ34: =IF($C34=$Z$17,$E34,0) -> 0 | AR34: =IF($C34=$Z$17,$F34,0) -> 0 | AT34: =IF(OR($G34=$AA$11,$G34=$AA$13,($G34=$AA$14),$G34=$AA$15),$AE34+$AG34+$AI34+$AK34+$AQ34,0) -> 0 | AU34: =IF(OR($G34=$AA$11,$G34=$AA$13,($G34=$AA$14),$G34=$AA$15),$AF34+$AH34+$AJ34+AL34+AR34,0) -> 0 | AV34: =IF($G34=$AA$12,$AE34+$AG34+$AI34+AK34+AQ34,0) -> 0 | AW34: =IF($G34=$AA$12,$AF34+$AH34+$AJ34+AL34+AR34,0) -> 0 | AY34: =IF(UPPER($I34) =$AB$12,IF($G34=$AA$12,$AV34,0),0) -> 0 | AZ34: =IF(UPPER($I34) =$AB$12,IF($G34<>$AA$12,$AT34,0),0) -> 0 | BA34: =IF(UPPER($I34) =$AB$12,IF($G34=$AA$12,$AW34,0),0) -> 0 | BB34: =IF(UPPER($I34) =$AB$12,IF($G34<>$AA$12,$AU34,0),0) -> 0 | BC34: =IF(UPPER($J34) =$AB$12,IF($G34=$AA$12,$AV34,0),0) -> 0 | BD34: =IF(UPPER($J34) =$AB$12,IF($G34<>$AA$12,$AT34,0),0) -> 0 | BE34: =IF(UPPER($J34) =$AB$12,IF($G34=$AA$12,$AW34,0),0) -> 0 | BF34: =IF(UPPER($J34) =$AB$12,IF($G34<>$AA$12,$AU34,0),0) -> 0 | BG34: =IF(UPPER($K34) =$AB$12,IF($G34=$AA$12,$AV34,0),0) -> 0 | BH34: =IF(UPPER($K34) =$AB$12,IF($G34<>$AA$12,$AT34,0),0) -> 0 | BI34: =IF(UPPER($K34) =$AB$12,IF($G34=$AA$12,$AW34,0),0) -> 0 | BJ34: =IF(UPPER($K34) =$AB$12,IF($G34<>$AA$12,$AU34,0),0) -> 0 | BL34: =IF(($E34+$F34>0), IF($G34=$AA$10,1,0),0) -> 0 | BM34: =IF(($E34+$F34<=0), IF($G34<>$AA$10,1,0),0) -> 0 | BN34: =IF(($E34+$F34>0), IF($C34=$AA$10,1,0),0) -> 0
AE35: =IF($C35=$Z$11,$E35,0) -> 0 | AF35: =IF($C35=$Z$11,$F35,0) -> 0 | AG35: =IF($C35=$Z$12,$E35,0) -> 0 | AH35: =IF($C35=$Z$12,$F35,0) -> 0 | AI35: =IF($C35=$Z$13,$E35,0) -> 0 | AJ35: =IF($C35=$Z$13,$F35,0) -> 0 | AK35: =IF($C35=$Z$14,$E35,0) -> 0 | AL35: =IF($C35=$Z$14,$F35,0) -> 0 | AM35: =IF($C35=$Z$15,$E35,0) -> 0 | AN35: =IF($C35=$Z$15,$F35,0) -> 0 | AO35: =IF($C35=$Z$16,$E35,0) -> 0 | AP35: =IF($C35=$Z$16,$F35,0) -> 0 | AQ35: =IF($C35=$Z$17,$E35,0) -> 0 | AR35: =IF($C35=$Z$17,$F35,0) -> 0 | AT35: =IF(OR($G35=$AA$11,$G35=$AA$13,($G35=$AA$14),$G35=$AA$15),$AE35+$AG35+$AI35+$AK35+$AQ35,0) -> 0 | AU35: =IF(OR($G35=$AA$11,$G35=$AA$13,($G35=$AA$14),$G35=$AA$15),$AF35+$AH35+$AJ35+AL35+AR35,0) -> 0 | AV35: =IF($G35=$AA$12,$AE35+$AG35+$AI35+AK35+AQ35,0) -> 0 | AW35: =IF($G35=$AA$12,$AF35+$AH35+$AJ35+AL35+AR35,0) -> 0 | AY35: =IF(UPPER($I35) =$AB$12,IF($G35=$AA$12,$AV35,0),0) -> 0 | AZ35: =IF(UPPER($I35) =$AB$12,IF($G35<>$AA$12,$AT35,0),0) -> 0 | BA35: =IF(UPPER($I35) =$AB$12,IF($G35=$AA$12,$AW35,0),0) -> 0 | BB35: =IF(UPPER($I35) =$AB$12,IF($G35<>$AA$12,$AU35,0),0) -> 0 | BC35: =IF(UPPER($J35) =$AB$12,IF($G35=$AA$12,$AV35,0),0) -> 0 | BD35: =IF(UPPER($J35) =$AB$12,IF($G35<>$AA$12,$AT35,0),0) -> 0 | BE35: =IF(UPPER($J35) =$AB$12,IF($G35=$AA$12,$AW35,0),0) -> 0 | BF35: =IF(UPPER($J35) =$AB$12,IF($G35<>$AA$12,$AU35,0),0) -> 0 | BG35: =IF(UPPER($K35) =$AB$12,IF($G35=$AA$12,$AV35,0),0) -> 0 | BH35: =IF(UPPER($K35) =$AB$12,IF($G35<>$AA$12,$AT35,0),0) -> 0 | BI35: =IF(UPPER($K35) =$AB$12,IF($G35=$AA$12,$AW35,0),0) -> 0 | BJ35: =IF(UPPER($K35) =$AB$12,IF($G35<>$AA$12,$AU35,0),0) -> 0 | BL35: =IF(($E35+$F35>0), IF($G35=$AA$10,1,0),0) -> 0 | BM35: =IF(($E35+$F35<=0), IF($G35<>$AA$10,1,0),0) -> 0 | BN35: =IF(($E35+$F35>0), IF($C35=$AA$10,1,0),0) -> 0
A36: 25 | L36: PAGINA 2
A37: 26 | AE37: =IF($C37=$Z$11,$E37,0) -> 0 | AF37: =IF($C37=$Z$11,$F37,0) -> 0 | AG37: =IF($C37=$Z$12,$E37,0) -> 0 | AH37: =IF($C37=$Z$12,$F37,0) -> 0 | AI37: =IF($C37=$Z$13,$E37,0) -> 0 | AJ37: =IF($C37=$Z$13,$F37,0) -> 0 | AK37: =IF($C37=$Z$14,$E37,0) -> 0 | AL37: =IF($C37=$Z$14,$F37,0) -> 0 | AM37: =IF($C37=$Z$15,$E37,0) -> 0 | AN37: =IF($C37=$Z$15,$F37,0) -> 0 | AO37: =IF($C37=$Z$16,$E37,0) -> 0 | AP37: =IF($C37=$Z$16,$F37,0) -> 0 | AQ37: =IF($C37=$Z$17,$E37,0) -> 0 | AR37: =IF($C37=$Z$17,$F37,0) -> 0 | AT37: =IF(OR($G37=$AA$11,$G37=$AA$13,($G37=$AA$14),$G37=$AA$15),$AE37+$AG37+$AI37+$AK37+$AQ37,0) -> 0 | AU37: =IF(OR($G37=$AA$11,$G37=$AA$13,($G37=$AA$14),$G37=$AA$15),$AF37+$AH37+$AJ37+AL37+AR37,0) -> 0 | AV37: =IF($G37=$AA$12,$AE37+$AG37+$AI37+AK37+AQ37,0) -> 0 | AW37: =IF($G37=$AA$12,$AF37+$AH37+$AJ37+AL37+AR37,0) -> 0 | AY37: =IF(UPPER($I37) =$AB$12,IF($G37=$AA$12,$AV37,0),0) -> 0 | AZ37: =IF(UPPER($I37) =$AB$12,IF($G37<>$AA$12,$AT37,0),0) -> 0 | BA37: =IF(UPPER($I37) =$AB$12,IF($G37=$AA$12,$AW37,0),0) -> 0 | BB37: =IF(UPPER($I37) =$AB$12,IF($G37<>$AA$12,$AU37,0),0) -> 0 | BC37: =IF(UPPER($J37) =$AB$12,IF($G37=$AA$12,$AV37,0),0) -> 0 | BD37: =IF(UPPER($J37) =$AB$12,IF($G37<>$AA$12,$AT37,0),0) -> 0 | BE37: =IF(UPPER($J37) =$AB$12,IF($G37=$AA$12,$AW37,0),0) -> 0 | BF37: =IF(UPPER($J37) =$AB$12,IF($G37<>$AA$12,$AU37,0),0) -> 0 | BG37: =IF(UPPER($K37) =$AB$12,IF($G37=$AA$12,$AV37,0),0) -> 0 | BH37: =IF(UPPER($K37) =$AB$12,IF($G37<>$AA$12,$AT37,0),0) -> 0 | BI37: =IF(UPPER($K37) =$AB$12,IF($G37=$AA$12,$AW37,0),0) -> 0 | BJ37: =IF(UPPER($K37) =$AB$12,IF($G37<>$AA$12,$AU37,0),0) -> 0 | BL37: =IF(($E37+$F37>0), IF($G37=$AA$10,1,0),0) -> 0 | BM37: =IF(($E37+$F37<=0), IF($G37<>$AA$10,1,0),0) -> 0 | BN37: =IF(($E37+$F37>0), IF($C37=$AA$10,1,0),0) -> 0
A38: 27 | AE38: =IF($C38=$Z$11,$E38,0) -> 0 | AF38: =IF($C38=$Z$11,$F38,0) -> 0 | AG38: =IF($C38=$Z$12,$E38,0) -> 0 | AH38: =IF($C38=$Z$12,$F38,0) -> 0 | AI38: =IF($C38=$Z$13,$E38,0) -> 0 | AJ38: =IF($C38=$Z$13,$F38,0) -> 0 | AK38: =IF($C38=$Z$14,$E38,0) -> 0 | AL38: =IF($C38=$Z$14,$F38,0) -> 0 | AM38: =IF($C38=$Z$15,$E38,0) -> 0 | AN38: =IF($C38=$Z$15,$F38,0) -> 0 | AO38: =IF($C38=$Z$16,$E38,0) -> 0 | AP38: =IF($C38=$Z$16,$F38,0) -> 0 | AQ38: =IF($C38=$Z$17,$E38,0) -> 0 | AR38: =IF($C38=$Z$17,$F38,0) -> 0 | AT38: =IF(OR($G38=$AA$11,$G38=$AA$13,($G38=$AA$14),$G38=$AA$15),$AE38+$AG38+$AI38+$AK38+$AQ38,0) -> 0 | AU38: =IF(OR($G38=$AA$11,$G38=$AA$13,($G38=$AA$14),$G38=$AA$15),$AF38+$AH38+$AJ38+AL38+AR38,0) -> 0 | AV38: =IF($G38=$AA$12,$AE38+$AG38+$AI38+AK38+AQ38,0) -> 0 | AW38: =IF($G38=$AA$12,$AF38+$AH38+$AJ38+AL38+AR38,0) -> 0 | AY38: =IF(UPPER($I38) =$AB$12,IF($G38=$AA$12,$AV38,0),0) -> 0 | AZ38: =IF(UPPER($I38) =$AB$12,IF($G38<>$AA$12,$AT38,0),0) -> 0 | BA38: =IF(UPPER($I38) =$AB$12,IF($G38=$AA$12,$AW38,0),0) -> 0 | BB38: =IF(UPPER($I38) =$AB$12,IF($G38<>$AA$12,$AU38,0),0) -> 0 | BC38: =IF(UPPER($J38) =$AB$12,IF($G38=$AA$12,$AV38,0),0) -> 0 | BD38: =IF(UPPER($J38) =$AB$12,IF($G38<>$AA$12,$AT38,0),0) -> 0 | BE38: =IF(UPPER($J38) =$AB$12,IF($G38=$AA$12,$AW38,0),0) -> 0 | BF38: =IF(UPPER($J38) =$AB$12,IF($G38<>$AA$12,$AU38,0),0) -> 0 | BG38: =IF(UPPER($K38) =$AB$12,IF($G38=$AA$12,$AV38,0),0) -> 0 | BH38: =IF(UPPER($K38) =$AB$12,IF($G38<>$AA$12,$AT38,0),0) -> 0 | BI38: =IF(UPPER($K38) =$AB$12,IF($G38=$AA$12,$AW38,0),0) -> 0 | BJ38: =IF(UPPER($K38) =$AB$12,IF($G38<>$AA$12,$AU38,0),0) -> 0 | BL38: =IF(($E38+$F38>0), IF($G38=$AA$10,1,0),0) -> 0 | BM38: =IF(($E38+$F38<=0), IF($G38<>$AA$10,1,0),0) -> 0 | BN38: =IF(($E38+$F38>0), IF($C38=$AA$10,1,0),0) -> 0
A39: 28 | AE39: =IF($C39=$Z$11,$E39,0) -> 0 | AF39: =IF($C39=$Z$11,$F39,0) -> 0 | AG39: =IF($C39=$Z$12,$E39,0) -> 0 | AH39: =IF($C39=$Z$12,$F39,0) -> 0 | AI39: =IF($C39=$Z$13,$E39,0) -> 0 | AJ39: =IF($C39=$Z$13,$F39,0) -> 0 | AK39: =IF($C39=$Z$14,$E39,0) -> 0 | AL39: =IF($C39=$Z$14,$F39,0) -> 0 | AM39: =IF($C39=$Z$15,$E39,0) -> 0 | AN39: =IF($C39=$Z$15,$F39,0) -> 0 | AO39: =IF($C39=$Z$16,$E39,0) -> 0 | AP39: =IF($C39=$Z$16,$F39,0) -> 0 | AQ39: =IF($C39=$Z$17,$E39,0) -> 0 | AR39: =IF($C39=$Z$17,$F39,0) -> 0 | AT39: =IF(OR($G39=$AA$11,$G39=$AA$13,($G39=$AA$14),$G39=$AA$15),$AE39+$AG39+$AI39+$AK39+$AQ39,0) -> 0 | AU39: =IF(OR($G39=$AA$11,$G39=$AA$13,($G39=$AA$14),$G39=$AA$15),$AF39+$AH39+$AJ39+AL39+AR39,0) -> 0 | AV39: =IF($G39=$AA$12,$AE39+$AG39+$AI39+AK39+AQ39,0) -> 0 | AW39: =IF($G39=$AA$12,$AF39+$AH39+$AJ39+AL39+AR39,0) -> 0 | AY39: =IF(UPPER($I39) =$AB$12,IF($G39=$AA$12,$AV39,0),0) -> 0 | AZ39: =IF(UPPER($I39) =$AB$12,IF($G39<>$AA$12,$AT39,0),0) -> 0 | BA39: =IF(UPPER($I39) =$AB$12,IF($G39=$AA$12,$AW39,0),0) -> 0 | BB39: =IF(UPPER($I39) =$AB$12,IF($G39<>$AA$12,$AU39,0),0) -> 0 | BC39: =IF(UPPER($J39) =$AB$12,IF($G39=$AA$12,$AV39,0),0) -> 0 | BD39: =IF(UPPER($J39) =$AB$12,IF($G39<>$AA$12,$AT39,0),0) -> 0 | BE39: =IF(UPPER($J39) =$AB$12,IF($G39=$AA$12,$AW39,0),0) -> 0 | BF39: =IF(UPPER($J39) =$AB$12,IF($G39<>$AA$12,$AU39,0),0) -> 0 | BG39: =IF(UPPER($K39) =$AB$12,IF($G39=$AA$12,$AV39,0),0) -> 0 | BH39: =IF(UPPER($K39) =$AB$12,IF($G39<>$AA$12,$AT39,0),0) -> 0 | BI39: =IF(UPPER($K39) =$AB$12,IF($G39=$AA$12,$AW39,0),0) -> 0 | BJ39: =IF(UPPER($K39) =$AB$12,IF($G39<>$AA$12,$AU39,0),0) -> 0 | BL39: =IF(($E39+$F39>0), IF($G39=$AA$10,1,0),0) -> 0 | BM39: =IF(($E39+$F39<=0), IF($G39<>$AA$10,1,0),0) -> 0 | BN39: =IF(($E39+$F39>0), IF($C39=$AA$10,1,0),0) -> 0
A40: 29 | AE40: =IF($C40=$Z$11,$E40,0) -> 0 | AF40: =IF($C40=$Z$11,$F40,0) -> 0 | AG40: =IF($C40=$Z$12,$E40,0) -> 0 | AH40: =IF($C40=$Z$12,$F40,0) -> 0 | AI40: =IF($C40=$Z$13,$E40,0) -> 0 | AJ40: =IF($C40=$Z$13,$F40,0) -> 0 | AK40: =IF($C40=$Z$14,$E40,0) -> 0 | AL40: =IF($C40=$Z$14,$F40,0) -> 0 | AM40: =IF($C40=$Z$15,$E40,0) -> 0 | AN40: =IF($C40=$Z$15,$F40,0) -> 0 | AO40: =IF($C40=$Z$16,$E40,0) -> 0 | AP40: =IF($C40=$Z$16,$F40,0) -> 0 | AQ40: =IF($C40=$Z$17,$E40,0) -> 0 | AR40: =IF($C40=$Z$17,$F40,0) -> 0 | AT40: =IF(OR($G40=$AA$11,$G40=$AA$13,($G40=$AA$14),$G40=$AA$15),$AE40+$AG40+$AI40+$AK40+$AQ40,0) -> 0 | AU40: =IF(OR($G40=$AA$11,$G40=$AA$13,($G40=$AA$14),$G40=$AA$15),$AF40+$AH40+$AJ40+AL40+AR40,0) -> 0 | AV40: =IF($G40=$AA$12,$AE40+$AG40+$AI40+AK40+AQ40,0) -> 0 | AW40: =IF($G40=$AA$12,$AF40+$AH40+$AJ40+AL40+AR40,0) -> 0 | AY40: =IF(UPPER($I40) =$AB$12,IF($G40=$AA$12,$AV40,0),0) -> 0 | AZ40: =IF(UPPER($I40) =$AB$12,IF($G40<>$AA$12,$AT40,0),0) -> 0 | BA40: =IF(UPPER($I40) =$AB$12,IF($G40=$AA$12,$AW40,0),0) -> 0 | BB40: =IF(UPPER($I40) =$AB$12,IF($G40<>$AA$12,$AU40,0),0) -> 0 | BC40: =IF(UPPER($J40) =$AB$12,IF($G40=$AA$12,$AV40,0),0) -> 0 | BD40: =IF(UPPER($J40) =$AB$12,IF($G40<>$AA$12,$AT40,0),0) -> 0 | BE40: =IF(UPPER($J40) =$AB$12,IF($G40=$AA$12,$AW40,0),0) -> 0 | BF40: =IF(UPPER($J40) =$AB$12,IF($G40<>$AA$12,$AU40,0),0) -> 0 | BG40: =IF(UPPER($K40) =$AB$12,IF($G40=$AA$12,$AV40,0),0) -> 0 | BH40: =IF(UPPER($K40) =$AB$12,IF($G40<>$AA$12,$AT40,0),0) -> 0 | BI40: =IF(UPPER($K40) =$AB$12,IF($G40=$AA$12,$AW40,0),0) -> 0 | BJ40: =IF(UPPER($K40) =$AB$12,IF($G40<>$AA$12,$AU40,0),0) -> 0 | BL40: =IF(($E40+$F40>0), IF($G40=$AA$10,1,0),0) -> 0 | BM40: =IF(($E40+$F40<=0), IF($G40<>$AA$10,1,0),0) -> 0 | BN40: =IF(($E40+$F40>0), IF($C40=$AA$10,1,0),0) -> 0
A41: 30 | AE41: =IF($C41=$Z$11,$E41,0) -> 0 | AF41: =IF($C41=$Z$11,$F41,0) -> 0 | AG41: =IF($C41=$Z$12,$E41,0) -> 0 | AH41: =IF($C41=$Z$12,$F41,0) -> 0 | AI41: =IF($C41=$Z$13,$E41,0) -> 0 | AJ41: =IF($C41=$Z$13,$F41,0) -> 0 | AK41: =IF($C41=$Z$14,$E41,0) -> 0 | AL41: =IF($C41=$Z$14,$F41,0) -> 0 | AM41: =IF($C41=$Z$15,$E41,0) -> 0 | AN41: =IF($C41=$Z$15,$F41,0) -> 0 | AO41: =IF($C41=$Z$16,$E41,0) -> 0 | AP41: =IF($C41=$Z$16,$F41,0) -> 0 | AQ41: =IF($C41=$Z$17,$E41,0) -> 0 | AR41: =IF($C41=$Z$17,$F41,0) -> 0 | AT41: =IF(OR($G41=$AA$11,$G41=$AA$13,($G41=$AA$14),$G41=$AA$15),$AE41+$AG41+$AI41+$AK41+$AQ41,0) -> 0 | AU41: =IF(OR($G41=$AA$11,$G41=$AA$13,($G41=$AA$14),$G41=$AA$15),$AF41+$AH41+$AJ41+AL41+AR41,0) -> 0 | AV41: =IF($G41=$AA$12,$AE41+$AG41+$AI41+AK41+AQ41,0) -> 0 | AW41: =IF($G41=$AA$12,$AF41+$AH41+$AJ41+AL41+AR41,0) -> 0 | AY41: =IF(UPPER($I41) =$AB$12,IF($G41=$AA$12,$AV41,0),0) -> 0 | AZ41: =IF(UPPER($I41) =$AB$12,IF($G41<>$AA$12,$AT41,0),0) -> 0 | BA41: =IF(UPPER($I41) =$AB$12,IF($G41=$AA$12,$AW41,0),0) -> 0 | BB41: =IF(UPPER($I41) =$AB$12,IF($G41<>$AA$12,$AU41,0),0) -> 0 | BC41: =IF(UPPER($J41) =$AB$12,IF($G41=$AA$12,$AV41,0),0) -> 0 | BD41: =IF(UPPER($J41) =$AB$12,IF($G41<>$AA$12,$AT41,0),0) -> 0 | BE41: =IF(UPPER($J41) =$AB$12,IF($G41=$AA$12,$AW41,0),0) -> 0 | BF41: =IF(UPPER($J41) =$AB$12,IF($G41<>$AA$12,$AU41,0),0) -> 0 | BG41: =IF(UPPER($K41) =$AB$12,IF($G41=$AA$12,$AV41,0),0) -> 0 | BH41: =IF(UPPER($K41) =$AB$12,IF($G41<>$AA$12,$AT41,0),0) -> 0 | BI41: =IF(UPPER($K41) =$AB$12,IF($G41=$AA$12,$AW41,0),0) -> 0 | BJ41: =IF(UPPER($K41) =$AB$12,IF($G41<>$AA$12,$AU41,0),0) -> 0 | BL41: =IF(($E41+$F41>0), IF($G41=$AA$10,1,0),0) -> 0 | BM41: =IF(($E41+$F41<=0), IF($G41<>$AA$10,1,0),0) -> 0 | BN41: =IF(($E41+$F41>0), IF($C41=$AA$10,1,0),0) -> 0
A42: 31 | AE42: =IF($C42=$Z$11,$E42,0) -> 0 | AF42: =IF($C42=$Z$11,$F42,0) -> 0 | AG42: =IF($C42=$Z$12,$E42,0) -> 0 | AH42: =IF($C42=$Z$12,$F42,0) -> 0 | AI42: =IF($C42=$Z$13,$E42,0) -> 0 | AJ42: =IF($C42=$Z$13,$F42,0) -> 0 | AK42: =IF($C42=$Z$14,$E42,0) -> 0 | AL42: =IF($C42=$Z$14,$F42,0) -> 0 | AM42: =IF($C42=$Z$15,$E42,0) -> 0 | AN42: =IF($C42=$Z$15,$F42,0) -> 0 | AO42: =IF($C42=$Z$16,$E42,0) -> 0 | AP42: =IF($C42=$Z$16,$F42,0) -> 0 | AQ42: =IF($C42=$Z$17,$E42,0) -> 0 | AR42: =IF($C42=$Z$17,$F42,0) -> 0 | AT42: =IF(OR($G42=$AA$11,$G42=$AA$13,($G42=$AA$14),$G42=$AA$15),$AE42+$AG42+$AI42+$AK42+$AQ42,0) -> 0 | AU42: =IF(OR($G42=$AA$11,$G42=$AA$13,($G42=$AA$14),$G42=$AA$15),$AF42+$AH42+$AJ42+AL42+AR42,0) -> 0 | AV42: =IF($G42=$AA$12,$AE42+$AG42+$AI42+AK42+AQ42,0) -> 0 | AW42: =IF($G42=$AA$12,$AF42+$AH42+$AJ42+AL42+AR42,0) -> 0 | AY42: =IF(UPPER($I42) =$AB$12,IF($G42=$AA$12,$AV42,0),0) -> 0 | AZ42: =IF(UPPER($I42) =$AB$12,IF($G42<>$AA$12,$AT42,0),0) -> 0 | BA42: =IF(UPPER($I42) =$AB$12,IF($G42=$AA$12,$AW42,0),0) -> 0 | BB42: =IF(UPPER($I42) =$AB$12,IF($G42<>$AA$12,$AU42,0),0) -> 0 | BC42: =IF(UPPER($J42) =$AB$12,IF($G42=$AA$12,$AV42,0),0) -> 0 | BD42: =IF(UPPER($J42) =$AB$12,IF($G42<>$AA$12,$AT42,0),0) -> 0 | BE42: =IF(UPPER($J42) =$AB$12,IF($G42=$AA$12,$AW42,0),0) -> 0 | BF42: =IF(UPPER($J42) =$AB$12,IF($G42<>$AA$12,$AU42,0),0) -> 0 | BG42: =IF(UPPER($K42) =$AB$12,IF($G42=$AA$12,$AV42,0),0) -> 0 | BH42: =IF(UPPER($K42) =$AB$12,IF($G42<>$AA$12,$AT42,0),0) -> 0 | BI42: =IF(UPPER($K42) =$AB$12,IF($G42=$AA$12,$AW42,0),0) -> 0 | BJ42: =IF(UPPER($K42) =$AB$12,IF($G42<>$AA$12,$AU42,0),0) -> 0 | BL42: =IF(($E42+$F42>0), IF($G42=$AA$10,1,0),0) -> 0 | BM42: =IF(($E42+$F42<=0), IF($G42<>$AA$10,1,0),0) -> 0 | BN42: =IF(($E42+$F42>0), IF($C42=$AA$10,1,0),0) -> 0
A43: 32 | AE43: =IF($C43=$Z$11,$E43,0) -> 0 | AF43: =IF($C43=$Z$11,$F43,0) -> 0 | AG43: =IF($C43=$Z$12,$E43,0) -> 0 | AH43: =IF($C43=$Z$12,$F43,0) -> 0 | AI43: =IF($C43=$Z$13,$E43,0) -> 0 | AJ43: =IF($C43=$Z$13,$F43,0) -> 0 | AK43: =IF($C43=$Z$14,$E43,0) -> 0 | AL43: =IF($C43=$Z$14,$F43,0) -> 0 | AM43: =IF($C43=$Z$15,$E43,0) -> 0 | AN43: =IF($C43=$Z$15,$F43,0) -> 0 | AO43: =IF($C43=$Z$16,$E43,0) -> 0 | AP43: =IF($C43=$Z$16,$F43,0) -> 0 | AQ43: =IF($C43=$Z$17,$E43,0) -> 0 | AR43: =IF($C43=$Z$17,$F43,0) -> 0 | AT43: =IF(OR($G43=$AA$11,$G43=$AA$13,($G43=$AA$14),$G43=$AA$15),$AE43+$AG43+$AI43+$AK43+$AQ43,0) -> 0 | AU43: =IF(OR($G43=$AA$11,$G43=$AA$13,($G43=$AA$14),$G43=$AA$15),$AF43+$AH43+$AJ43+AL43+AR43,0) -> 0 | AV43: =IF($G43=$AA$12,$AE43+$AG43+$AI43+AK43+AQ43,0) -> 0 | AW43: =IF($G43=$AA$12,$AF43+$AH43+$AJ43+AL43+AR43,0) -> 0 | AY43: =IF(UPPER($I43) =$AB$12,IF($G43=$AA$12,$AV43,0),0) -> 0 | AZ43: =IF(UPPER($I43) =$AB$12,IF($G43<>$AA$12,$AT43,0),0) -> 0 | BA43: =IF(UPPER($I43) =$AB$12,IF($G43=$AA$12,$AW43,0),0) -> 0 | BB43: =IF(UPPER($I43) =$AB$12,IF($G43<>$AA$12,$AU43,0),0) -> 0 | BC43: =IF(UPPER($J43) =$AB$12,IF($G43=$AA$12,$AV43,0),0) -> 0 | BD43: =IF(UPPER($J43) =$AB$12,IF($G43<>$AA$12,$AT43,0),0) -> 0 | BE43: =IF(UPPER($J43) =$AB$12,IF($G43=$AA$12,$AW43,0),0) -> 0 | BF43: =IF(UPPER($J43) =$AB$12,IF($G43<>$AA$12,$AU43,0),0) -> 0 | BG43: =IF(UPPER($K43) =$AB$12,IF($G43=$AA$12,$AV43,0),0) -> 0 | BH43: =IF(UPPER($K43) =$AB$12,IF($G43<>$AA$12,$AT43,0),0) -> 0 | BI43: =IF(UPPER($K43) =$AB$12,IF($G43=$AA$12,$AW43,0),0) -> 0 | BJ43: =IF(UPPER($K43) =$AB$12,IF($G43<>$AA$12,$AU43,0),0) -> 0 | BL43: =IF(($E43+$F43>0), IF($G43=$AA$10,1,0),0) -> 0 | BM43: =IF(($E43+$F43<=0), IF($G43<>$AA$10,1,0),0) -> 0 | BN43: =IF(($E43+$F43>0), IF($C43=$AA$10,1,0),0) -> 0
A44: 33 | AE44: =IF($C44=$Z$11,$E44,0) -> 0 | AF44: =IF($C44=$Z$11,$F44,0) -> 0 | AG44: =IF($C44=$Z$12,$E44,0) -> 0 | AH44: =IF($C44=$Z$12,$F44,0) -> 0 | AI44: =IF($C44=$Z$13,$E44,0) -> 0 | AJ44: =IF($C44=$Z$13,$F44,0) -> 0 | AK44: =IF($C44=$Z$14,$E44,0) -> 0 | AL44: =IF($C44=$Z$14,$F44,0) -> 0 | AM44: =IF($C44=$Z$15,$E44,0) -> 0 | AN44: =IF($C44=$Z$15,$F44,0) -> 0 | AO44: =IF($C44=$Z$16,$E44,0) -> 0 | AP44: =IF($C44=$Z$16,$F44,0) -> 0 | AQ44: =IF($C44=$Z$17,$E44,0) -> 0 | AR44: =IF($C44=$Z$17,$F44,0) -> 0 | AT44: =IF(OR($G44=$AA$11,$G44=$AA$13,($G44=$AA$14),$G44=$AA$15),$AE44+$AG44+$AI44+$AK44+$AQ44,0) -> 0 | AU44: =IF(OR($G44=$AA$11,$G44=$AA$13,($G44=$AA$14),$G44=$AA$15),$AF44+$AH44+$AJ44+AL44+AR44,0) -> 0 | AV44: =IF($G44=$AA$12,$AE44+$AG44+$AI44+AK44+AQ44,0) -> 0 | AW44: =IF($G44=$AA$12,$AF44+$AH44+$AJ44+AL44+AR44,0) -> 0 | AY44: =IF(UPPER($I44) =$AB$12,IF($G44=$AA$12,$AV44,0),0) -> 0 | AZ44: =IF(UPPER($I44) =$AB$12,IF($G44<>$AA$12,$AT44,0),0) -> 0 | BA44: =IF(UPPER($I44) =$AB$12,IF($G44=$AA$12,$AW44,0),0) -> 0 | BB44: =IF(UPPER($I44) =$AB$12,IF($G44<>$AA$12,$AU44,0),0) -> 0 | BC44: =IF(UPPER($J44) =$AB$12,IF($G44=$AA$12,$AV44,0),0) -> 0 | BD44: =IF(UPPER($J44) =$AB$12,IF($G44<>$AA$12,$AT44,0),0) -> 0 | BE44: =IF(UPPER($J44) =$AB$12,IF($G44=$AA$12,$AW44,0),0) -> 0 | BF44: =IF(UPPER($J44) =$AB$12,IF($G44<>$AA$12,$AU44,0),0) -> 0 | BG44: =IF(UPPER($K44) =$AB$12,IF($G44=$AA$12,$AV44,0),0) -> 0 | BH44: =IF(UPPER($K44) =$AB$12,IF($G44<>$AA$12,$AT44,0),0) -> 0 | BI44: =IF(UPPER($K44) =$AB$12,IF($G44=$AA$12,$AW44,0),0) -> 0 | BJ44: =IF(UPPER($K44) =$AB$12,IF($G44<>$AA$12,$AU44,0),0) -> 0 | BL44: =IF(($E44+$F44>0), IF($G44=$AA$10,1,0),0) -> 0 | BM44: =IF(($E44+$F44<=0), IF($G44<>$AA$10,1,0),0) -> 0 | BN44: =IF(($E44+$F44>0), IF($C44=$AA$10,1,0),0) -> 0
A45: 34 | AE45: =IF($C45=$Z$11,$E45,0) -> 0 | AF45: =IF($C45=$Z$11,$F45,0) -> 0 | AG45: =IF($C45=$Z$12,$E45,0) -> 0 | AH45: =IF($C45=$Z$12,$F45,0) -> 0 | AI45: =IF($C45=$Z$13,$E45,0) -> 0 | AJ45: =IF($C45=$Z$13,$F45,0) -> 0 | AK45: =IF($C45=$Z$14,$E45,0) -> 0 | AL45: =IF($C45=$Z$14,$F45,0) -> 0 | AM45: =IF($C45=$Z$15,$E45,0) -> 0 | AN45: =IF($C45=$Z$15,$F45,0) -> 0 | AO45: =IF($C45=$Z$16,$E45,0) -> 0 | AP45: =IF($C45=$Z$16,$F45,0) -> 0 | AQ45: =IF($C45=$Z$17,$E45,0) -> 0 | AR45: =IF($C45=$Z$17,$F45,0) -> 0 | AT45: =IF(OR($G45=$AA$11,$G45=$AA$13,($G45=$AA$14),$G45=$AA$15),$AE45+$AG45+$AI45+$AK45+$AQ45,0) -> 0 | AU45: =IF(OR($G45=$AA$11,$G45=$AA$13,($G45=$AA$14),$G45=$AA$15),$AF45+$AH45+$AJ45+AL45+AR45,0) -> 0 | AV45: =IF($G45=$AA$12,$AE45+$AG45+$AI45+AK45+AQ45,0) -> 0 | AW45: =IF($G45=$AA$12,$AF45+$AH45+$AJ45+AL45+AR45,0) -> 0 | AY45: =IF(UPPER($I45) =$AB$12,IF($G45=$AA$12,$AV45,0),0) -> 0 | AZ45: =IF(UPPER($I45) =$AB$12,IF($G45<>$AA$12,$AT45,0),0) -> 0 | BA45: =IF(UPPER($I45) =$AB$12,IF($G45=$AA$12,$AW45,0),0) -> 0 | BB45: =IF(UPPER($I45) =$AB$12,IF($G45<>$AA$12,$AU45,0),0) -> 0 | BC45: =IF(UPPER($J45) =$AB$12,IF($G45=$AA$12,$AV45,0),0) -> 0 | BD45: =IF(UPPER($J45) =$AB$12,IF($G45<>$AA$12,$AT45,0),0) -> 0 | BE45: =IF(UPPER($J45) =$AB$12,IF($G45=$AA$12,$AW45,0),0) -> 0 | BF45: =IF(UPPER($J45) =$AB$12,IF($G45<>$AA$12,$AU45,0),0) -> 0 | BG45: =IF(UPPER($K45) =$AB$12,IF($G45=$AA$12,$AV45,0),0) -> 0 | BH45: =IF(UPPER($K45) =$AB$12,IF($G45<>$AA$12,$AT45,0),0) -> 0 | BI45: =IF(UPPER($K45) =$AB$12,IF($G45=$AA$12,$AW45,0),0) -> 0 | BJ45: =IF(UPPER($K45) =$AB$12,IF($G45<>$AA$12,$AU45,0),0) -> 0 | BL45: =IF(($E45+$F45>0), IF($G45=$AA$10,1,0),0) -> 0 | BM45: =IF(($E45+$F45<=0), IF($G45<>$AA$10,1,0),0) -> 0 | BN45: =IF(($E45+$F45>0), IF($C45=$AA$10,1,0),0) -> 0
...

Sheet RIMBORSO KM
G1: Doc. rimborso KM rev.04
F2: Nota Spese | G2: Elenco tragitti per rimborso km - modulo
A4: ELENCO TRAGITTI PER RIMBORSO KM
E6: Causale:
E7: Autore:
F8: Firma:
A9: N° | B9: Data | C9: Causale | G9: km
A10: 1
A11: 2
A12: 3
A13: 4
A14: 5
A15: 6
A16: 7
A17: 8
A18: 9
A19: 10
A20: 11
A21: 12
... A56: 47
A57: TOTALE DA RIMBORSARE: | D57: =G57*0.3 -> 0 | F57: TOTALE Km : | G57: =SUM(G10:G56) -> 0

Sheet Note di compilazione
A1: NOTE PER LA COMPILAZIONE:
A3: Il modulo deve essere utilizzato da tutto coloro che, per conto dell'azienda, hanno sostenuto delle spese sia in contanti che con carta di credito aziendale.
A5: Il primo foglio " RIEPILOGO RIMBORSO SPESE" va compilato nella parte "dati trasferta" solo in caso di trasferte e spese diverse raggruppabili mensilmente ( scontrini e rimborso km )
A6: Nel secondo foglio " RIMBORSO SPESE" vanno elencati uno per uno gli scontrini e/o fatture riportando il numero sequenziale a penna sul documento
A7: I campi vanno compilati utilizzando la tendina sulla destra di ogni colonna ad esclusione della colonna" D " CAUSALE" dove va inserito il dettaglio della spesa effettuata.
